Workbook
Name Standards: Tables!$A$2:$A$17

Sheet COVER
B2: FILE NAME: | C2: ="IC"&C15&"-"&C23&"-"&C22&C8 -> IC13C-241218-10KansasROARCarbon-3
B4: ISIRF Isotope Cube INLET SUBMISSION FORM -- AS OF 4/29/2024
B6: PESD Project: | C6: Kansas ROAR and Oregon PINE
B7: Project Description: | C7: The Kansas ROAR projects investigates soil health practices influences over nitrate leaching (Soil Samples collected from 0-8 inches in Kansas farmlands)
B8: Project Code & Tray ID for file name: | C8: KansasROARCarbon-3
B9: Investigator: | C9: Compton
B10: Affiliation: | C10: =VLOOKUP($C$9,Table1[],3) -> FEB
B11: Address: | C11: =VLOOKUP($C$9,Table1[],5) -> Corvallis MOD 130
B12: Email: | C12: =VLOOKUP($C$9,Table1[],6) -> compton.jana@epa.gov
B13: Phone: | C13: =VLOOKUP($C$9,Table1[],7) -> 4620
B14: Weigh Person: | C14: Janice Chatfield
B15: Analyses (13C, 15N, 34S): | C15: 13C
B16: Sample %C
B17: Sample %N
B18: Sample %S
B19: Sample Description (Matrix): | C19: Soil
B20: Enriched Samples? (Y or N): | C20: No
B21: HazardousSamples? (Y or N): | C21: No
B22: Investigator ID# | C22: =VLOOKUP($C$9,Table1[],4) -> 10
B23: Date: (YYMMDD) | C23: 241218
B26: DIRECTIONS:
B27: 1. Obtain the ISIRF Solid Submission Form from the mass spectrometer operator.
B28: 2. Fill in the yellow shaded regions of the Cover, and Investigator Data Sheets (34 samples maximum).
B29: 3. Rename this file with the File name in dark tan box above, and e-mail to Lisandra Trine
B30: 4. ISIRF will identify standards and sample weights needed, and print the weighsheet.
B31: 5. ISIRF will give your weigh sheet to the trained weigh person identified above.
B32: 6. Have Weigh person submit samples and Weigh Sheet to the IRMS operator.
B34: INDEX
B35: Tab | C35: Contents
B36: Cover | C36: PI Project and sample discription
B37: Investigator Data | C37: PI Sample identification, and Results
B38: Weigh Sheet | C38: Printable Sheet for hand entering weights
B39: Investigator QA Data | C39: PI and ISIRF Quality Assurance Information
B40: ISIRF Raw | C40: ISIRF use for raw data entery
B41: ISIRF 15N | C41: ISIRF use for d15N summary
B42: ISIRF 13C | C42: ISIRF use for d13C summary
B43: ISIRF 34S | C43: ISIRF use for d34S summary
B44: Tables | C44: ISIRF use for updated tables
B45: Revisions | C45: ISIRF revision summary

Sheet Investigator Data
B2: FILE NAME: | C2: =COVER!C2 -> IC13C-241218-10KansasROARCarbon-3 | I2: User Data
A3: Sample # | B3: Sample ID | C3: Target Wt. | D3: %C | E3: δ13C | F3: %N | G3: δ15N | H3: C/N
A4: Rep 1 | B4: 20231120_W1_H | C4: 25 | D4: =IF(COUNT('ISIRF RAW'!M12,'ISIRF RAW'!M56)=0,"",AVERAGE('ISIRF RAW'!M12,'ISIRF RAW'!M56)) -> 1.447397 | E4: =IF(COUNT('ISIRF RAW'!O12,'ISIRF RAW'!O56)=0,"",AVERAGE('ISIRF RAW'!O12,'ISIRF RAW'!O56)) -> -17.516797 | F4: =IF(COUNT('ISIRF RAW'!J12,'ISIRF RAW'!J56)=0,"",AVERAGE('ISIRF RAW'!J12,'ISIRF RAW'!J56)) -> 0.23881289 | G4: =IF(COUNT('ISIRF RAW'!L12,'ISIRF RAW'!L56)=0,"", AVERAGE('ISIRF RAW'!L12,'ISIRF RAW'!L56)) -> 6.0309836 | H4: =D4/F4 -> 6.0607991
A5: 2 | B5: 20240407_E1_A | C5: 25 | D5: =IF(COUNT('ISIRF RAW'!M13)=0,"",'ISIRF RAW'!M13) -> 1.4578363 | E5: =IF(COUNT('ISIRF RAW'!O13)=0,"",'ISIRF RAW'!O13) -> -18.634865 | F5: =IF(COUNT('ISIRF RAW'!J13)=0,"",'ISIRF RAW'!J13) -> 0.24384169 | G5: =IF(COUNT('ISIRF RAW'!L13)=0,"",'ISIRF RAW'!L13) -> 5.7231284 | H5: =D5/F5 -> 5.9786177
A6: 3 | B6: 20240407_E1_B | C6: 25 | D6: =IF(COUNT('ISIRF RAW'!M14)=0,"",'ISIRF RAW'!M14) -> 1.1877115 | E6: =IF(COUNT('ISIRF RAW'!O14)=0,"",'ISIRF RAW'!O14) -> -18.980546 | F6: =IF(COUNT('ISIRF RAW'!J14)=0,"",'ISIRF RAW'!J14) -> 0.22203126 | G6: =IF(COUNT('ISIRF RAW'!L14)=0,"",'ISIRF RAW'!L14) -> 6.1203509 | H6: =D6/F6 -> 5.3492987
A7: 4 | B7: 20240407_E1_C | C7: 25 | D7: =IF(COUNT('ISIRF RAW'!M15)=0,"",'ISIRF RAW'!M15) -> 1.0882062 | E7: =IF(COUNT('ISIRF RAW'!O15)=0,"",'ISIRF RAW'!O15) -> -17.928809 | F7: =IF(COUNT('ISIRF RAW'!J15)=0,"",'ISIRF RAW'!J15) -> 0.2021982 | G7: =IF(COUNT('ISIRF RAW'!L15)=0,"",'ISIRF RAW'!L15) -> 7.0235017 | H7: =D7/F7 -> 5.3818789
A8: 5 | B8: 20240407_E1_D | C8: 25 | D8: =IF(COUNT('ISIRF RAW'!M16)=0,"",'ISIRF RAW'!M16) -> 0.87695938 | E8: =IF(COUNT('ISIRF RAW'!O16)=0,"",'ISIRF RAW'!O16) -> -19.366854 | F8: =IF(COUNT('ISIRF RAW'!J16)=0,"",'ISIRF RAW'!J16) -> 0.1926948 | G8: =IF(COUNT('ISIRF RAW'!L16)=0,"",'ISIRF RAW'!L16) -> 5.1773368 | H8: =D8/F8 -> 4.5510277
A9: 6 | B9: 20240407_E1_E | C9: 25 | D9: =IF(COUNT('ISIRF RAW'!M17)=0,"",'ISIRF RAW'!M17) -> 1.2789841 | E9: =IF(COUNT('ISIRF RAW'!O17)=0,"",'ISIRF RAW'!O17) -> -18.186247 | F9: =IF(COUNT('ISIRF RAW'!J17)=0,"",'ISIRF RAW'!J17) -> 0.21679652 | G9: =IF(COUNT('ISIRF RAW'!L17)=0,"",'ISIRF RAW'!L17) -> 6.6652954 | H9: =D9/F9 -> 5.8994676
A10: 7 | B10: 20240407_E1_F | C10: 25 | D10: =IF(COUNT('ISIRF RAW'!M18)=0,"",'ISIRF RAW'!M18) -> 1.0395341 | E10: =IF(COUNT('ISIRF RAW'!O18)=0,"",'ISIRF RAW'!O18) -> -17.687159 | F10: =IF(COUNT('ISIRF RAW'!J18)=0,"",'ISIRF RAW'!J18) -> 0.20904362 | G10: =IF(COUNT('ISIRF RAW'!L18)=0,"",'ISIRF RAW'!L18) -> 5.9113498 | H10: =D10/F10 -> 4.9728093
A11: 8 | B11: 20240407_E1_G | C11: 25 | D11: =IF(COUNT('ISIRF RAW'!M19)=0,"",'ISIRF RAW'!M19) -> 0.92634415 | E11: =IF(COUNT('ISIRF RAW'!O19)=0,"",'ISIRF RAW'!O19) -> -18.820987 | F11: =IF(COUNT('ISIRF RAW'!J19)=0,"",'ISIRF RAW'!J19) -> 0.19180323 | G11: =IF(COUNT('ISIRF RAW'!L19)=0,"",'ISIRF RAW'!L19) -> 6.3929006 | H11: =D11/F11 -> 4.8296588
A12: 9 | B12: 20240407_E1_H | C12: 25 | D12: =IF(COUNT('ISIRF RAW'!M20)=0,"",'ISIRF RAW'!M20) -> 0.97958492 | E12: =IF(COUNT('ISIRF RAW'!O20)=0,"",'ISIRF RAW'!O20) -> -19.93126 | F12: =IF(COUNT('ISIRF RAW'!J20)=0,"",'ISIRF RAW'!J20) -> 0.19174212 | G12: =IF(COUNT('ISIRF RAW'!L20)=0,"",'ISIRF RAW'!L20) -> 5.6871041 | H12: =D12/F12 -> 5.1088667
A13: 10 | B13: 20240407_E1_I | C13: 25 | D13: =IF(COUNT('ISIRF RAW'!M22)=0,"",'ISIRF RAW'!M22) -> 1.057665 | E13: =IF(COUNT('ISIRF RAW'!O22)=0,"",'ISIRF RAW'!O22) -> -16.912024 | F13: =IF(COUNT('ISIRF RAW'!J22)=0,"",'ISIRF RAW'!J22) -> 0.21000635 | G13: =IF(COUNT('ISIRF RAW'!L22)=0,"",'ISIRF RAW'!L22) -> 5.8139297 | H13: =D13/F13 -> 5.0363475
A14: 11 | B14: 20240407_E2_A | C14: 25 | D14: =IF(COUNT('ISIRF RAW'!M23)=0,"",'ISIRF RAW'!M23) -> 0.97146888 | E14: =IF(COUNT('ISIRF RAW'!O23)=0,"",'ISIRF RAW'!O23) -> -15.263654 | F14: =IF(COUNT('ISIRF RAW'!J23)=0,"",'ISIRF RAW'!J23) -> 0.21043163 | G14: =IF(COUNT('ISIRF RAW'!L23)=0,"",'ISIRF RAW'!L23) -> 6.3412139 | H14: =D14/F14 -> 4.6165536
A15: 12 | B15: 20240407_E2_B | C15: 25 | D15: =IF(COUNT('ISIRF RAW'!M24)=0,"",'ISIRF RAW'!M24) -> 0.69674496 | E15: =IF(COUNT('ISIRF RAW'!O24)=0,"",'ISIRF RAW'!O24) -> -10.016053 | F15: =IF(COUNT('ISIRF RAW'!J24)=0,"",'ISIRF RAW'!J24) -> 0.15152513 | G15: =IF(COUNT('ISIRF RAW'!L24)=0,"",'ISIRF RAW'!L24) -> 5.3711217 | H15: =D15/F15 -> 4.5982137
A16: 13 | B16: 20240407_E2_C | C16: 25 | D16: =IF(COUNT('ISIRF RAW'!M25)=0,"",'ISIRF RAW'!M25) -> 2.3777769 | E16: =IF(COUNT('ISIRF RAW'!O25)=0,"",'ISIRF RAW'!O25) -> -16.092748 | F16: =IF(COUNT('ISIRF RAW'!J25)=0,"",'ISIRF RAW'!J25) -> 0.30895486 | G16: =IF(COUNT('ISIRF RAW'!L25)=0,"",'ISIRF RAW'!L25) -> 6.6512728 | H16: =D16/F16 -> 7.6961952
A17: Rep 14 | B17: 20240407_E2_D | C17: 25 | D17: =IF(COUNT('ISIRF RAW'!M26,'ISIRF RAW'!M27)=0,"",AVERAGE('ISIRF RAW'!M26,'ISIRF RAW'!M27)) -> 2.6758166 | E17: =IF(COUNT('ISIRF RAW'!O26,'ISIRF RAW'!O27)=0,"",AVERAGE('ISIRF RAW'!O26,'ISIRF RAW'!O27)) -> -16.917573 | F17: =IF(COUNT('ISIRF RAW'!J26,'ISIRF RAW'!J27)=0,"",AVERAGE('ISIRF RAW'!J26,'ISIRF RAW'!J27)) -> 0.33263131 | G17: =IF(COUNT('ISIRF RAW'!L26,'ISIRF RAW'!L27)=0,"", AVERAGE('ISIRF RAW'!L26,'ISIRF RAW'!L27)) -> 7.3373171 | H17: =D17/F17 -> 8.0443919
A18: 15 | B18: 20240407_E2_E | C18: 25 | D18: =IF(COUNT('ISIRF RAW'!M28)=0,"",'ISIRF RAW'!M28) -> 1.9886621 | E18: =IF(COUNT('ISIRF RAW'!O28)=0,"",'ISIRF RAW'!O28) -> -16.924723 | F18: =IF(COUNT('ISIRF RAW'!J28)=0,"",'ISIRF RAW'!J28) -> 0.28429224 | G18: =IF(COUNT('ISIRF RAW'!L28)=0,"",'ISIRF RAW'!L28) -> 7.4901936 | H18: =D18/F18 -> 6.9951331
A19: 16 | B19: 20240407_E2_F | C19: 25 | D19: =IF(COUNT('ISIRF RAW'!M29)=0,"",'ISIRF RAW'!M29) -> 2.1084519 | E19: =IF(COUNT('ISIRF RAW'!O29)=0,"",'ISIRF RAW'!O29) -> -17.68129 | F19: =IF(COUNT('ISIRF RAW'!J29)=0,"",'ISIRF RAW'!J29) -> 0.30106466 | G19: =IF(COUNT('ISIRF RAW'!L29)=0,"",'ISIRF RAW'!L29) -> 7.2876062 | H19: =D19/F19 -> 7.0033192
A20: 17 | B20: 20240407_E2_G | C20: 25 | D20: =IF(COUNT('ISIRF RAW'!M30)=0,"",'ISIRF RAW'!M30) -> 2.3499685 | E20: =IF(COUNT('ISIRF RAW'!O30)=0,"",'ISIRF RAW'!O30) -> -17.584874 | F20: =IF(COUNT('ISIRF RAW'!J30)=0,"",'ISIRF RAW'!J30) -> 0.32504081 | G20: =IF(COUNT('ISIRF RAW'!L30)=0,"",'ISIRF RAW'!L30) -> 7.1792402 | H20: =D20/F20 -> 7.2297644
A21: 18 | B21: 20240407_E3_A | C21: 25 | D21: =IF(COUNT('ISIRF RAW'!M31)=0,"",'ISIRF RAW'!M31) -> 2.5227545 | E21: =IF(COUNT('ISIRF RAW'!O31)=0,"",'ISIRF RAW'!O31) -> -18.258097 | F21: =IF(COUNT('ISIRF RAW'!J31)=0,"",'ISIRF RAW'!J31) -> 0.33302896 | G21: =IF(COUNT('ISIRF RAW'!L31)=0,"",'ISIRF RAW'!L31) -> 7.2720251 | H21: =D21/F21 -> 7.5751806
A22: 19 | B22: 20240407_E3_A_Dup | C22: 25 | D22: =IF(COUNT('ISIRF RAW'!M37)=0,"",'ISIRF RAW'!M37) -> 2.2476812 | E22: =IF(COUNT('ISIRF RAW'!O37)=0,"",'ISIRF RAW'!O37) -> -18.07135 | F22: =IF(COUNT('ISIRF RAW'!J37)=0,"",'ISIRF RAW'!J37) -> 0.30396959 | G22: =IF(COUNT('ISIRF RAW'!L37)=0,"",'ISIRF RAW'!L37) -> 6.6455028 | H22: =D22/F22 -> 7.3944278
A23: 20 | B23: 20240407_E3_B | C23: 25 | D23: =IF(COUNT('ISIRF RAW'!M38)=0,"",'ISIRF RAW'!M38) -> 2.0430232 | E23: =IF(COUNT('ISIRF RAW'!O38)=0,"",'ISIRF RAW'!O38) -> -17.436017 | F23: =IF(COUNT('ISIRF RAW'!J38)=0,"",'ISIRF RAW'!J38) -> 0.28838761 | G23: =IF(COUNT('ISIRF RAW'!L38)=0,"",'ISIRF RAW'!L38) -> 7.3234342 | H23: =D23/F23 -> 7.0842962
A24: 21 | B24: 20240407_E3_C | C24: 25 | D24: =IF(COUNT('ISIRF RAW'!M39)=0,"",'ISIRF RAW'!M39) -> 2.0760193 | E24: =IF(COUNT('ISIRF RAW'!O39)=0,"",'ISIRF RAW'!O39) -> -17.862555 | F24: =IF(COUNT('ISIRF RAW'!J39)=0,"",'ISIRF RAW'!J39) -> 0.28732609 | G24: =IF(COUNT('ISIRF RAW'!L39)=0,"",'ISIRF RAW'!L39) -> 7.2132287 | H24: =D24/F24 -> 7.2253072
A25: 22 | B25: 20240407_E3_D | C25: 25 | D25: =IF(COUNT('ISIRF RAW'!M40)=0,"",'ISIRF RAW'!M40) -> 2.0353622 | E25: =IF(COUNT('ISIRF RAW'!O40)=0,"",'ISIRF RAW'!O40) -> -17.030797 | F25: =IF(COUNT('ISIRF RAW'!J40)=0,"",'ISIRF RAW'!J40) -> 0.28640103 | G25: =IF(COUNT('ISIRF RAW'!L40)=0,"",'ISIRF RAW'!L40) -> 6.8575659 | H25: =D25/F25 -> 7.1066858
A26: 23 | B26: 20240407_E3_E | C26: 25 | D26: =IF(COUNT('ISIRF RAW'!M41)=0,"",'ISIRF RAW'!M41) -> 2.0671267 | E26: =IF(COUNT('ISIRF RAW'!O41)=0,"",'ISIRF RAW'!O41) -> -15.722165 | F26: =IF(COUNT('ISIRF RAW'!J41)=0,"",'ISIRF RAW'!J41) -> 0.28773965 | G26: =IF(COUNT('ISIRF RAW'!L41)=0,"",'ISIRF RAW'!L41) -> 6.7670227 | H26: =D26/F26 -> 7.1840175
A27: 24 | B27: 20240407_E3_F | C27: 25 | D27: =IF(COUNT('ISIRF RAW'!M42)=0,"",'ISIRF RAW'!M42) -> 1.8415892 | E27: =IF(COUNT('ISIRF RAW'!O42)=0,"",'ISIRF RAW'!O42) -> -16.04413 | F27: =IF(COUNT('ISIRF RAW'!J42)=0,"",'ISIRF RAW'!J42) -> 0.27487339 | G27: =IF(COUNT('ISIRF RAW'!L42)=0,"",'ISIRF RAW'!L42) -> 6.4527602 | H27: =D27/F27 -> 6.6997725
A28: 25 | B28: 20240407_E3_G | C28: 25 | D28: =IF(COUNT('ISIRF RAW'!M43)=0,"",'ISIRF RAW'!M43) -> 2.2665794 | E28: =IF(COUNT('ISIRF RAW'!O43)=0,"",'ISIRF RAW'!O43) -> -15.62253 | F28: =IF(COUNT('ISIRF RAW'!J43)=0,"",'ISIRF RAW'!J43) -> 0.30661752 | G28: =IF(COUNT('ISIRF RAW'!L43)=0,"",'ISIRF RAW'!L43) -> 6.448637 | H28: =D28/F28 -> 7.3922045
A29: 26 | B29: 20240407_E3_H | C29: 25 | D29: =IF(COUNT('ISIRF RAW'!M44)=0,"",'ISIRF RAW'!M44) -> 2.4184878 | E29: =IF(COUNT('ISIRF RAW'!O44)=0,"",'ISIRF RAW'!O44) -> -15.568359 | F29: =IF(COUNT('ISIRF RAW'!J44)=0,"",'ISIRF RAW'!J44) -> 0.3163503 | G29: =IF(COUNT('ISIRF RAW'!L44)=0,"",'ISIRF RAW'!L44) -> 6.9817264 | H29: =D29/F29 -> 7.6449676
A30: 27 | B30: 20240407_E3_I | C30: 25 | D30: =IF(COUNT('ISIRF RAW'!M45)=0,"",'ISIRF RAW'!M45) -> 1.8484477 | E30: =IF(COUNT('ISIRF RAW'!O45)=0,"",'ISIRF RAW'!O45) -> -15.767069 | F30: =IF(COUNT('ISIRF RAW'!J45)=0,"",'ISIRF RAW'!J45) -> 0.2882185 | G30: =IF(COUNT('ISIRF RAW'!L45)=0,"",'ISIRF RAW'!L45) -> 6.3962872 | H30: =D30/F30 -> 6.4133555
A31: 28 | B31: 20240407_S2_A | C31: 25 | D31: =IF(COUNT('ISIRF RAW'!M47)=0,"",'ISIRF RAW'!M47) -> 3.2714808 | E31: =IF(COUNT('ISIRF RAW'!O47)=0,"",'ISIRF RAW'!O47) -> -25.484609 | F31: =IF(COUNT('ISIRF RAW'!J47)=0,"",'ISIRF RAW'!J47) -> 0.39199154 | G31: =IF(COUNT('ISIRF RAW'!L47)=0,"",'ISIRF RAW'!L47) -> 4.5553426 | H31: =D31/F31 -> 8.3457945
A32: 29 | B32: 20240407_S2_B | C32: 25 | D32: =IF(COUNT('ISIRF RAW'!M48)=0,"",'ISIRF RAW'!M48) -> 12.194634 | E32: =IF(COUNT('ISIRF RAW'!O48)=0,"",'ISIRF RAW'!O48) -> -25.509947 | F32: =IF(COUNT('ISIRF RAW'!J48)=0,"",'ISIRF RAW'!J48) -> 1.0857378 | G32: =IF(COUNT('ISIRF RAW'!L48)=0,"",'ISIRF RAW'!L48) -> 7.3198599 | H32: =D32/F32 -> 11.231657
A33: 30 | B33: 20240407_S2_C | C33: 25 | D33: =IF(COUNT('ISIRF RAW'!M49)=0,"",'ISIRF RAW'!M49) -> 0.81545152 | E33: =IF(COUNT('ISIRF RAW'!O49)=0,"",'ISIRF RAW'!O49) -> -11.457435 | F33: =IF(COUNT('ISIRF RAW'!J49)=0,"",'ISIRF RAW'!J49) -> 0.16302347 | G33: =IF(COUNT('ISIRF RAW'!L49)=0,"",'ISIRF RAW'!L49) -> 5.7371641 | H33: =D33/F33 -> 5.0020497
A34: 31 | B34: 20240407_S2_D | C34: 25 | D34: =IF(COUNT('ISIRF RAW'!M50)=0,"",'ISIRF RAW'!M50) -> 2.8678131 | E34: =IF(COUNT('ISIRF RAW'!O50)=0,"",'ISIRF RAW'!O50) -> -25.755183 | F34: =IF(COUNT('ISIRF RAW'!J50)=0,"",'ISIRF RAW'!J50) -> 0.3350239 | G34: =IF(COUNT('ISIRF RAW'!L50)=0,"",'ISIRF RAW'!L50) -> 4.4930012 | H34: =D34/F34 -> 8.5600254
A35: 32 | B35: 20240407_S2_E | C35: 25 | D35: =IF(COUNT('ISIRF RAW'!M51)=0,"",'ISIRF RAW'!M51) -> 1.8198609 | E35: =IF(COUNT('ISIRF RAW'!O51)=0,"",'ISIRF RAW'!O51) -> -18.987914 | F35: =IF(COUNT('ISIRF RAW'!J51)=0,"",'ISIRF RAW'!J51) -> 0.25721107 | G35: =IF(COUNT('ISIRF RAW'!L51)=0,"",'ISIRF RAW'!L51) -> 5.2744406 | H35: =D35/F35 -> 7.0753597
A36: 33 | B36: 20240407_S2_F | C36: 25 | D36: =IF(COUNT('ISIRF RAW'!M52)=0,"",'ISIRF RAW'!M52) -> 0.63177772 | E36: =IF(COUNT('ISIRF RAW'!O52)=0,"",'ISIRF RAW'!O52) -> -11.193808 | F36: =IF(COUNT('ISIRF RAW'!J52)=0,"",'ISIRF RAW'!J52) -> 0.15060426 | G36: =IF(COUNT('ISIRF RAW'!L52)=0,"",'ISIRF RAW'!L52) -> 6.0700865 | H36: =D36/F36 -> 4.1949525
A37: 34 | B37: 20240407_S2_G | C37: 25 | D37: =IF(COUNT('ISIRF RAW'!M53)=0,"",'ISIRF RAW'!M53) -> 1.7304288 | E37: =IF(COUNT('ISIRF RAW'!O53)=0,"",'ISIRF RAW'!O53) -> -17.15423 | F37: =IF(COUNT('ISIRF RAW'!J53)=0,"",'ISIRF RAW'!J53) -> 0.2339959 | G37: =IF(COUNT('ISIRF RAW'!L53)=0,"",'ISIRF RAW'!L53) -> 6.0369666 | H37: =D37/F37 -> 7.3951244
A38: 35 | B38: 20240407_S2_H | C38: 25 | D38: =IF(COUNT('ISIRF RAW'!M54)=0,"",'ISIRF RAW'!M54) -> 1.6784548 | E38: =IF(COUNT('ISIRF RAW'!O54)=0,"",'ISIRF RAW'!O54) -> -16.656556 | F38: =IF(COUNT('ISIRF RAW'!J54)=0,"",'ISIRF RAW'!J54) -> 0.24608527 | G38: =IF(COUNT('ISIRF RAW'!L54)=0,"",'ISIRF RAW'!L54) -> 5.5216338 | H38: =D38/F38 -> 6.8206228
A39: 36 | B39: 20240407_S2_I | C39: 25 | D39: =IF(COUNT('ISIRF RAW'!M55)=0,"",'ISIRF RAW'!M55) -> 1.4758365 | E39: =IF(COUNT('ISIRF RAW'!O55)=0,"",'ISIRF RAW'!O55) -> -17.140011 | F39: =IF(COUNT('ISIRF RAW'!J55)=0,"",'ISIRF RAW'!J55) -> 0.22915797 | G39: =IF(COUNT('ISIRF RAW'!L55)=0,"",'ISIRF RAW'!L55) -> 5.4253729 | H39: =D39/F39 -> 6.440258

Sheet Weigh Sheet
A1: =COVER!B4 -> ISIRF Isotope Cube INLET SUBMISSION FORM -- AS OF 4/29/2024 | F1: #Samples | G1: =COUNTA('Investigator Data'!B4:B39) -> 36
B2: FILE NAME: | C2: =COVER!C2 -> IC13C-241218-10KansasROARCarbon-3 | E2: WRITE FULL FILE NAME ON TRAY!!
A3: WEIGH INFO: | D3: Wt. (mg) | E3: Calibration Info. Balance:
A4: Sample Description: | C4: =COVER!C19 -> Soil | E4: Date | F4: Balance Log Book
A5: Sample %N, %C: | C5: =COVER!C16 -> 0
A6: Analyses: | C6: =COVER!C15 -> 13C
A7: Weigh Person: | C7: =COVER!C14 -> Janice Chatfield
A8: Sample Weight:
A9: QC.Std: | C9: ISIRF Ulva | D9: =VLOOKUP(C9,Tables!A2:C17,3,FALSE) -> 1.2
A10: Cal-H.Std: | C10: ISIRF Chitin | D10: =VLOOKUP(C10,Tables!A2:C17,3,FALSE) -> 1 | E10: ISIRF USE ONLY
A11: Cal-L.Std: | C11: ISIRF Bamboo | D11: =VLOOKUP(C11,Tables!A2:C17,3,FALSE) -> 1.5 | E11: DATE SUBMITTED: | G11: =IF(COUNTA(COVER!C23)=0,"",COVER!C23) -> 241218
A12: QA Std: | C12: NBS 1575 Pine Needles | D12: =VLOOKUP(C12,Tables!A2:C17,3,FALSE) -> 6.5 | E12: DATE RUN: | G12: =IF(COUNTA('ISIRF RAW'!B2)=0,"",'ISIRF RAW'!B2) -> 44278
A13: Sample Cup | C13: Tin | D13: 5 X 9 | E13: ANALYST: | G13: =IF(COUNTA('ISIRF RAW'!B3)=0,"",'ISIRF RAW'!B3) -> LSDT
A14: CO2 Dilution: @ 40 psi | D14: 5 | E14: Mode of Operation | G14: =COVER!C15 -> 13C
A16: ISIRF# | B16: Well# | C16: Sample ID | D16: Target Wt. | E16: Sample Wt. | F16: Seq.
A17: ="IC"&COVER!C$15&COVER!C$23&"-"&COVER!C$22&F17 -> IC13C241218-101 | B17: A1 | C17: blank | F17: 1
A18: ="IC"&COVER!C$15&COVER!C$23&"-"&COVER!C$22&F18 -> IC13C241218-102 | B18: A2 | C18: blank | F18: =F17+1 -> 2
A19: ="IC"&COVER!C$15&COVER!C$23&"-"&COVER!C$22&F19 -> IC13C241218-103 | B19: A3 | C19: =$C$9 -> ISIRF Ulva | D19: =$D$9 -> 1.2 | E19: 1.203 | F19: =F18+1 -> 3
A20: ="IC"&COVER!C$15&COVER!C$23&"-"&COVER!C$22&F20 -> IC13C241218-104 | B20: A4 | C20: =$C$10 -> ISIRF Chitin | D20: =$D$10 -> 1 | E20: 0.963 | F20: =F19+1 -> 4
A21: ="IC"&COVER!C$15&COVER!C$23&"-"&COVER!C$22&F21 -> IC13C241218-105 | B21: A5 | C21: =$C$11 -> ISIRF Bamboo | D21: =$D$11 -> 1.5 | E21: 1.446 | F21: =F20+1 -> 5
A22: ="IC"&COVER!C$15&COVER!C$23&"-"&COVER!C$22&F22 -> IC13C241218-106 | B22: A6 | C22: =C12 -> NBS 1575 Pine Needles | D22: =D12 -> 6.5 | E22: 6.792 | F22: =F21+1 -> 6
A23: ="IC"&COVER!C$15&COVER!C$23&"-"&COVER!C$22&F23 -> IC13C241218-107 | B23: A7 | C23: =IF('Investigator Data'!B4="","","R1-"&'Investigator Data'!B4) -> R1-20231120_W1_H | D23: =IF('Investigator Data'!C4="",$D$8,'Investigator Data'!C4) -> 25 | E23: 24.273 | F23: =F22+1 -> 7
A24: ="IC"&COVER!C$15&COVER!C$23&"-"&COVER!C$22&F24 -> IC13C241218-108 | B24: A8 | C24: =IF('Investigator Data'!B5="","",'Investigator Data'!B5) -> 20240407_E1_A | D24: =IF('Investigator Data'!C5="",$D$8,'Investigator Data'!C5) -> 25 | E24: 24.242 | F24: =F23+1 -> 8
A25: ="IC"&COVER!C$15&COVER!C$23&"-"&COVER!C$22&F25 -> IC13C241218-109 | B25: A9 | C25: =IF('Investigator Data'!B6="","",'Investigator Data'!B6) -> 20240407_E1_B | D25: =IF('Investigator Data'!C6="",$D$8,'Investigator Data'!C6) -> 25 | E25: 25.014 | F25: =F24+1 -> 9
A26: ="IC"&COVER!C$15&COVER!C$23&"-"&COVER!C$22&F26 -> IC13C241218-1010 | B26: A10 | C26: =IF('Investigator Data'!B7="","",'Investigator Data'!B7) -> 20240407_E1_C | D26: =IF('Investigator Data'!C7="",$D$8,'Investigator Data'!C7) -> 25 | E26: 26.885 | F26: =F25+1 -> 10
A27: ="IC"&COVER!C$15&COVER!C$23&"-"&COVER!C$22&F27 -> IC13C241218-1011 | B27: A11 | C27: =IF('Investigator Data'!B8="","",'Investigator Data'!B8) -> 20240407_E1_D | D27: =IF('Investigator Data'!C8="",$D$8,'Investigator Data'!C8) -> 25 | E27: 26.484 | F27: =F26+1 -> 11
A28: ="IC"&COVER!C$15&COVER!C$23&"-"&COVER!C$22&F28 -> IC13C241218-1012 | B28: A12 | C28: =IF('Investigator Data'!B9="","",'Investigator Data'!B9) -> 20240407_E1_E | D28: =IF('Investigator Data'!C9="",$D$8,'Investigator Data'!C9) -> 25 | E28: 24.553 | F28: =F27+1 -> 12
A29: ="IC"&COVER!C$15&COVER!C$23&"-"&COVER!C$22&F29 -> IC13C241218-1013 | B29: B1 | C29: =IF('Investigator Data'!B10="","",'Investigator Data'!B10) -> 20240407_E1_F | D29: =IF('Investigator Data'!C10="",$D$8,'Investigator Data'!C10) -> 25 | E29: 24.685 | F29: =F28+1 -> 13
A30: ="IC"&COVER!C$15&COVER!C$23&"-"&COVER!C$22&F30 -> IC13C241218-1014 | B30: B2 | C30: =IF('Investigator Data'!B11="","",'Investigator Data'!B11) -> 20240407_E1_G | D30: =IF('Investigator Data'!C11="",$D$8,'Investigator Data'!C11) -> 25 | E30: 24.501 | F30: =F29+1 -> 14
A31: ="IC"&COVER!C$15&COVER!C$23&"-"&COVER!C$22&F31 -> IC13C241218-1015 | B31: B3 | C31: =IF('Investigator Data'!B12="","",'Investigator Data'!B12) -> 20240407_E1_H | D31: =IF('Investigator Data'!C12="",$D$8,'Investigator Data'!C12) -> 25 | E31: 26.34 | F31: =F30+1 -> 15
A32: ="IC"&COVER!C$15&COVER!C$23&"-"&COVER!C$22&F32 -> IC13C241218-1016 | B32: B4 | C32: =$C$9 -> ISIRF Ulva | D32: =$D$9 -> 1.2 | E32: 1.163 | F32: =F31+1 -> 16
A33: ="IC"&COVER!C$15&COVER!C$23&"-"&COVER!C$22&F33 -> IC13C241218-1017 | B33: B5 | C33: =IF('Investigator Data'!B13="","",'Investigator Data'!B13) -> 20240407_E1_I | D33: =IF('Investigator Data'!C13="",$D$8,'Investigator Data'!C13) -> 25 | E33: 25.862 | F33: =F32+1 -> 17
A34: ="IC"&COVER!C$15&COVER!C$23&"-"&COVER!C$22&F34 -> IC13C241218-1018 | B34: B6 | C34: =IF('Investigator Data'!B14="","",'Investigator Data'!B14) -> 20240407_E2_A | D34: =IF('Investigator Data'!C14="",$D$8,'Investigator Data'!C14) -> 25 | E34: 25.869 | F34: =F33+1 -> 18
A35: ="IC"&COVER!C$15&COVER!C$23&"-"&COVER!C$22&F35 -> IC13C241218-1019 | B35: B7 | C35: =IF('Investigator Data'!B15="","",'Investigator Data'!B15) -> 20240407_E2_B | D35: =IF('Investigator Data'!C15="",$D$8,'Investigator Data'!C15) -> 25 | E35: 24.585 | F35: =F34+1 -> 19
A36: ="IC"&COVER!C$15&COVER!C$23&"-"&COVER!C$22&F36 -> IC13C241218-1020 | B36: B8 | C36: =IF('Investigator Data'!B16="","",'Investigator Data'!B16) -> 20240407_E2_C | D36: =IF('Investigator Data'!C16="",$D$8,'Investigator Data'!C16) -> 25 | E36: 25.415 | F36: =F35+1 -> 20
A37: ="IC"&COVER!C$15&COVER!C$23&"-"&COVER!C$22&F37 -> IC13C241218-1021 | B37: B9 | C37: =IF('Investigator Data'!B17="","","R2-"&'Investigator Data'!B17) -> R2-20240407_E2_D | D37: =IF('Investigator Data'!C17="",$D$8,'Investigator Data'!C17) -> 25 | E37: 25.872 | F37: =F36+1 -> 21
A38: ="IC"&COVER!C$15&COVER!C$23&"-"&COVER!C$22&F38 -> IC13C241218-1022 | B38: B10 | C38: =IF('Investigator Data'!B17="","","R2-"&'Investigator Data'!B17) -> R2-20240407_E2_D | D38: =IF('Investigator Data'!C17="",$D$8,'Investigator Data'!C17) -> 25 | E38: 24.998 | F38: =F37+1 -> 22
A39: ="IC"&COVER!C$15&COVER!C$23&"-"&COVER!C$22&F39 -> IC13C241218-1023 | B39: B11 | C39: =IF('Investigator Data'!B18="","",'Investigator Data'!B18) -> 20240407_E2_E | D39: =IF('Investigator Data'!C18="",$D$8,'Investigator Data'!C18) -> 25 | E39: 24.524 | F39: =F38+1 -> 23
A40: ="IC"&COVER!C$15&COVER!C$23&"-"&COVER!C$22&F40 -> IC13C241218-1024 | B40: B12 | C40: =IF('Investigator Data'!B19="","",'Investigator Data'!B19) -> 20240407_E2_F | D40: =IF('Investigator Data'!C19="",$D$8,'Investigator Data'!C19) -> 25 | E40: 25.322 | F40: =F39+1 -> 24
A41: ="IC"&COVER!C$15&COVER!C$23&"-"&COVER!C$22&F41 -> IC13C241218-1025 | B41: C1 | C41: =IF('Investigator Data'!B20="","",'Investigator Data'!B20) -> 20240407_E2_G | D41: =IF('Investigator Data'!C20="",$D$8,'Investigator Data'!C20) -> 25 | E41: 24.373 | F41: =F40+1 -> 25
...

Sheet ISIRF RAW
A1: ISIRF USE ONLY
A2: DATE RUN: | B2: 44278
A3: ANALYST: | B3: LSDT | D3: FILE NAME: | E3: =COVER!C2 -> IC13C-241218-10KansasROARCarbon-3
A4: METHOD: | B4: 13C
A5: Sample Name | B5: Line | C5: Sample Wt (mg) | D5: Mass 28 nA | E5: N2 Area | F5: Mass 44 nA | G5: CO2 Area | H5: Mass 64 nA | I5: SO2 Area | J5: Wt % N | K5: 15N ‰ Air | L5: 15N ‰ Air Corrected | M5: Wt % C | N5: 13C ‰ pdb | O5: 13C ‰ pdb Corrected | P5: Wt % S | Q5: 34S ‰ pdb | R5: 34S ‰ pdb Corrected | S5: Date | T5: Filename
A6: ='Weigh Sheet'!C17 -> blank | B6: 7 | C6: 37.5 | D6: 0.073872258 | E6: 1698372 | F6: 0 | G6: 0 | J6: 0.099202039 | K6: -1.3950239 | L6: -1.671633 | M6: 0 | N6: 0.14078431 | O6: -0.31926822 | S6: 45740.687 | T6: IC15N-241218-10KansasRoarCarbon-3_1.raw
A7: ='Weigh Sheet'!C18 -> blank | B7: 8 | C7: 37.5 | D7: 0.015689169 | E7: 368016 | F7: 0 | G7: 0 | J7: 0.094538242 | K7: -14.308157 | L7: -14.16627 | M7: 0 | N7: 0.11872043 | O7: -0.34156758 | S7: 45740.695 | T7: IC15N-241218-10KansasRoarCarbon-3_2.raw
A8: ='Weigh Sheet'!C19 -> ISIRF Ulva | B8: 9 | C8: 1.203 | D8: 4.4609385 | E8: 71002552 | F8: 5.5944675 | G8: 56886720 | J8: 4.1283299 | K8: 8.0850502 | L8: 7.5012053 | M8: 32.893523 | N8: -12.198084 | O8: -12.789826 | S8: 45740.703 | T8: IC15N-241218-10KansasRoarCarbon-3_3.raw
A9: ='Weigh Sheet'!C20 -> ISIRF Chitin | B9: 10 | C9: 0.963 | D9: 5.6857765 | E9: 89403248 | F9: 6.131893 | G9: 62863428 | J9: 6.4136891 | K9: -4.7520801 | L9: -4.9198917 | M9: 45.407268 | N9: -20.645407 | O9: -21.327304 | S9: 45740.711 | T9: IC15N-241218-10KansasRoarCarbon-3_4.raw
A10: ='Weigh Sheet'!C21 -> ISIRF Bamboo | B10: 11 | C10: 1.446 | D10: 3.8349592 | E10: 61901156 | F10: 8.791895 | G10: 92055536 | J10: 3.0516232 | K10: 2.3249376 | L10: 1.9277698 | M10: 44.225859 | N10: -29.626781 | O10: -30.404534 | S10: 45740.719 | T10: IC15N-241218-10KansasRoarCarbon-3_5.raw
A11: ='Weigh Sheet'!C22 -> NBS 1575 Pine Needles | B11: 12 | C11: 6.792 | D11: 6.4396345 | E11: 112044144 | F11: 34.312516 | G11: 500603232 | J11: 1.2213563 | K11: 0.95404778 | L11: 0.60130857 | M11: 51.545291 | N11: -25.088587 | O11: -25.817906 | S11: 45740.727 | T11: IC15N-241218-10KansasRoarCarbon-3_6.raw
A12: ='Weigh Sheet'!C23 -> R1-20231120_W1_H | B12: 13 | C12: 24.273 | D12: 2.5873242 | E12: 49507624 | F12: 4.526065 | G12: 47949100 | J12: 0.2381934 | K12: 6.4019085 | L12: 5.8726118 | M12: 1.3821212 | N12: -16.785135 | O12: -17.425833 | S12: 45740.735 | T12: IC15N-241218-10KansasRoarCarbon-3_7.raw
A13: ='Weigh Sheet'!C24 -> 20240407_E1_A | B13: 14 | C13: 24.242 | D13: 2.6496403 | E13: 49481328 | F13: 4.8292 | G13: 50602072 | J13: 0.24384169 | K13: 6.2474183 | L13: 5.7231284 | M13: 1.4578363 | N13: -17.9814 | O13: -18.634865 | S13: 45740.743 | T13: IC15N-241218-10KansasRoarCarbon-3_8.raw
A14: ='Weigh Sheet'!C25 -> 20240407_E1_B | B14: 15 | C14: 25.014 | D14: 2.2771167 | E14: 43382128 | F14: 4.0157155 | G14: 42491452 | J14: 0.22203126 | K14: 6.6579454 | L14: 6.1203509 | M14: 1.1877115 | N14: -18.32343 | O14: -18.980546 | S14: 45740.75 | T14: IC15N-241218-10KansasRoarCarbon-3_9.raw
A15: ='Weigh Sheet'!C26 -> 20240407_E1_C | B15: 16 | C15: 26.885 | D15: 2.138498 | E15: 40126776 | F15: 3.9645938 | G15: 41831892 | J15: 0.2021982 | K15: 7.5913464 | L15: 7.0235017 | M15: 1.0882062 | N15: -17.282799 | O15: -17.928809 | S15: 45740.758 | T15: IC15N-241218-10KansasRoarCarbon-3_10.raw
A16: ='Weigh Sheet'!C27 -> 20240407_E1_D | B16: 17 | C16: 26.484 | D16: 1.8330494 | E16: 35081264 | F16: 3.192868 | G16: 33109652 | J16: 0.1926948 | K16: 5.6833459 | L16: 5.1773368 | M16: 0.87695938 | N16: -18.705658 | O16: -19.366854 | S16: 45740.766 | T16: IC15N-241218-10KansasRoarCarbon-3_11.raw
A17: ='Weigh Sheet'!C28 -> 20240407_E1_E | B17: 18 | C17: 24.553 | D17: 2.2640015 | E17: 42677968 | F17: 4.3259935 | G17: 44885780 | J17: 0.21679652 | K17: 7.2211423 | L17: 6.6652954 | M17: 1.2789841 | N17: -17.537519 | O17: -18.186247 | S17: 45740.774 | T17: IC15N-241218-10KansasRoarCarbon-3_12.raw
... A61: ='Weigh Sheet'!C72 -> NBS 1575 Pine Needles | B61: 62 | C61: 6.873 | D61: 6.4289025 | E61: 117563456 | F61: 34.45842 | G61: 507203456 | J61: 1.2808622 | K61: 0.80463767 | L61: 0.45674064 | M61: 51.62033 | N61: -25.235221 | O61: -25.966105 | S61: 45741.12 | T61: IC15N-241218-10KansasRoarCarbon-3_56.raw
A62: Standard | B62: Run Type | C62: Actual d15N | D62: %N | E62: Actual d13C | F62: %C | G62: Actual d34S | H62: %S | I62: Slope d15N | J62: Intrcpt | K62: Slope d13C | L62: Intrcpt | M62: Slope d34S | N62: Intrcpt
A63: ISIRF Ulva | B63: QC.STD | C63: 7.4989403 | D63: 4.2927354 | E63: -12.890511 | F63: 33.294438 | I63: 0.96759141 | J63: -0.32181986 | K63: 1.0106727 | L63: -0.46155508
A64: ISIRF Chitin | B64: Cal-H.STD | C64: -5.0093785 | D64: 6.5259675 | E64: -21.201039 | F64: 44.925159
A65: ISIRF Bamboo | B65: Cal-L.STD | C65: 2.0694573 | D65: 3.0463773 | E65: -30.291664 | F65: 45.850178
A66: NBS 1575 Pine Needles | B66: Isotope QC | C66: 0.36348603 | D66: 1.1397949 | E66: -25.808178 | F66: 52.254104

Sheet Investigator QA Data
E2: FILE NAME: | F2: =COVER!C2 -> IC13C-241218-10KansasROARCarbon-3
A4: Quality Assurance data for Carbon: | E4: d13C | I4: %C | M4: Precision of carbon data
C5: Sample | D5: Actual | E5: Meas. | F5: Var. | G5: s.d. | H5: Actual | I5: Meas. | J5: Var. | K5: r. s.d. | L5: N | M5: d13C | O5: =IF(SUM(L7:L11)<2,"",SQRT((SUMPRODUCT(F6:F11,L6:L11))/SUM(L6:L11))) -> 0.1232671
A6: NIST Certified Isotope Standard - QC | C6: ='ISIRF 13C'!A7 -> NBS 1575 Pine Needles | D6: ='ISIRF 13C'!C7 -> -25.808178 | E6: ='ISIRF 13C'!B33 -> -25.890863 | F6: ='ISIRF 13C'!C33 -> 0.0054946423 | G6: ='ISIRF 13C'!D33 -> 0.074125854 | H6: ='ISIRF 13C'!D7 -> 52.254104 | I6: ='ISIRF 13C'!E33 -> 51.553406 | J6: ='ISIRF 13C'!F33 -> 0.0040015174 | K6: ='ISIRF 13C'!G33 -> 0.0012270295 | L6: ='ISIRF 13C'!H33 -> 3 | M6: [C] % | O6: =AVERAGE(K6:K11) -> 0.033802045
A7: Conc Cal Std - Isotope QC Std | C7: ='ISIRF 13C'!D11 -> ISIRF Ulva | D7: ='ISIRF 13C'!C4 -> -12.890511 | E7: ='ISIRF 13C'!B30 -> -12.889084 | F7: ='ISIRF 13C'!C30 -> 0.024479141 | G7: ='ISIRF 13C'!D30 -> 0.15645811 | H7: ='ISIRF 13C'!D4 -> 33.294438 | I7: ='ISIRF 13C'!E30 -> 33.509499 | J7: ='ISIRF 13C'!F30 -> 0.8278945 | K7: ='ISIRF 13C'!G30 -> 0.027153109 | L7: ='ISIRF 13C'!H30 -> 5 | M7: Accuracy of carbon data
A8: Conc QC Std - Isotope High Cal Std | C8: ='ISIRF 13C'!A5 -> ISIRF Chitin | D8: ='ISIRF 13C'!C5 -> -21.201039 | E8: ='ISIRF 13C'!B31 -> -21.211343 | F8: ='ISIRF 13C'!C31 -> 0.015800556 | G8: ='ISIRF 13C'!D31 -> 0.12570026 | H8: ='ISIRF 13C'!D5 -> 44.925159 | I8: ='ISIRF 13C'!E31 -> 46.049389 | J8: ='ISIRF 13C'!F31 -> 0.4334643 | K8: ='ISIRF 13C'!G31 -> 0.014297259 | L8: ='ISIRF 13C'!H31 -> 3 | M8: d13C | O8: =IF(COUNT(E6:E7)=0,"",D6-E6) -> 0.082685101
A9: Conc QC Std - Isotope Low Cal Std | C9: ='ISIRF 13C'!A6 -> ISIRF Bamboo | D9: ='ISIRF 13C'!C6 -> -30.291664 | E9: ='ISIRF 13C'!B32 -> -30.283739 | F9: ='ISIRF 13C'!C32 -> 0.013382332 | G9: ='ISIRF 13C'!D32 -> 0.11568203 | H9: ='ISIRF 13C'!D6 -> 45.850178 | I9: ='ISIRF 13C'!E32 -> 44.365154 | J9: ='ISIRF 13C'!F32 -> 0.90607348 | K9: ='ISIRF 13C'!G32 -> 0.021455553 | L9: ='ISIRF 13C'!H32 -> 3 | M9: [C] % | O9: =(H6-I6) -> 0.70069759
A10: Replicate Sample 1 | C10: ='Investigator Data'!B4 -> 20231120_W1_H | E10: ='ISIRF 13C'!B28 -> -17.516797 | F10: ='ISIRF 13C'!C28 -> 0.016548727 | G10: ='ISIRF 13C'!D28 -> 0.12864185 | I10: ='ISIRF 13C'!E28 -> 1.447397 | J10: ='ISIRF 13C'!F28 -> 0.0085218657 | K10: ='ISIRF 13C'!G28 -> 0.06377929 | L10: ='ISIRF 13C'!H28 -> 2
A11: Replicate Sample 2 | C11: ='Investigator Data'!B17 -> 20240407_E2_D | E11: ='ISIRF 13C'!B29 -> -16.917573 | F11: ='ISIRF 13C'!C29 -> 0.0069901302 | G11: ='ISIRF 13C'!D29 -> 0.083606999 | I11: ='ISIRF 13C'!E29 -> 2.6758166 | J11: ='ISIRF 13C'!F29 -> 0.040167672 | K11: ='ISIRF 13C'!G29 -> 0.074900029 | L11: ='ISIRF 13C'!H29 -> 2
A13: Quality Assurance Data for Nitrogen: | E13: d15N | I13: %N | M13: Precision of nitrogen data
C14: Sample | D14: Actual | E14: Meas. | F14: Var. | G14: s.d. | H14: Actual | I14: Meas. | J14: Var. | K14: r.s.d. | L14: N | M14: d15N | O14: =IF(SUM(L16:L20)<2,"",SQRT(SUMPRODUCT(F15:F20,L15:L20)/SUM(L15:L20))) -> 0.12667563
A15: NIST Certified Isotope Standard - QC | C15: ='ISIRF 15N'!A7 -> NBS 1575 Pine Needles | D15: ='ISIRF 15N'!C7 -> 0.36348603 | E15: ='ISIRF 15N'!B33 -> 0.46872056 | F15: ='ISIRF 15N'!C33 -> 0.016134707 | G15: ='ISIRF 15N'!D33 -> 0.12702247 | H15: ='ISIRF 15N'!D7 -> 1.1397949 | I15: ='ISIRF 15N'!E33 -> 1.2619882 | J15: ='ISIRF 15N'!F33 -> 0.0012402948 | K15: ='ISIRF 15N'!G33 -> 0.027906615 | L15: ='ISIRF 15N'!H33 -> 3 | M15: [N] % | O15: =AVERAGE(K15:K20) -> 0.024771979
A16: Conc Cal Std - Isotope QC Std | C16: ='ISIRF 15N'!A4 -> ISIRF Ulva | D16: ='ISIRF 15N'!C4 -> 7.4989403 | E16: ='ISIRF 15N'!B30 -> 7.5205279 | F16: ='ISIRF 15N'!C30 -> 0.013384648 | G16: ='ISIRF 15N'!D30 -> 0.11569204 | H16: ='ISIRF 15N'!D4 -> 4.2927354 | I16: ='ISIRF 15N'!E30 -> 4.2789882 | J16: ='ISIRF 15N'!F30 -> 0.043693963 | K16: ='ISIRF 15N'!G30 -> 0.04885057 | L16: ='ISIRF 15N'!H30 -> 5 | M16: Accuracy of nitrogen data
A17: Conc QC Std - Isotope High Cal Std | C17: ='ISIRF 15N'!A5 -> ISIRF Chitin | D17: ='ISIRF 15N'!C5 -> -5.0093785 | E17: ='ISIRF 15N'!B31 -> -4.9775203 | F17: ='ISIRF 15N'!C31 -> 0.0042543877 | G17: ='ISIRF 15N'!D31 -> 0.065225668 | H17: ='ISIRF 15N'!D5 -> 6.5259675 | I17: ='ISIRF 15N'!E31 -> 6.5145893 | J17: ='ISIRF 15N'!F31 -> 0.0086352642 | K17: ='ISIRF 15N'!G31 -> 0.01426431 | L17: ='ISIRF 15N'!H31 -> 3 | M17: d15N | O17: =IF(COUNT(E15:E16)=0,"",D15-E15) -> -0.10523453
A18: Conc QC Std - Isotope Low Cal Std | C18: ='ISIRF 15N'!A6 -> ISIRF Bamboo | D18: ='ISIRF 15N'!C6 -> 2.0694573 | E18: ='ISIRF 15N'!B32 -> 2.0016198 | F18: ='ISIRF 15N'!C32 -> 0.0046394184 | G18: ='ISIRF 15N'!D32 -> 0.068113276 | H18: ='ISIRF 15N'!D6 -> 3.0463773 | I18: ='ISIRF 15N'!E32 -> 3.0806675 | J18: ='ISIRF 15N'!F32 -> 0.0037681967 | K18: ='ISIRF 15N'!G32 -> 0.019926084 | L18: ='ISIRF 15N'!H32 -> 3 | M18: [N] % | O18: =IF(COUNT(I15,I17:I18)=0,"",H15-I15) -> -0.12219332
A19: Replicate Sample 1 | C19: ='Investigator Data'!B4 -> 20231120_W1_H | E19: ='ISIRF 15N'!B28 -> 6.0309836 | F19: ='ISIRF 15N'!C28 -> 0.050163256 | G19: ='ISIRF 15N'!D28 -> 0.22397155 | I19: ='ISIRF 15N'!E28 -> 0.23881289 | J19: ='ISIRF 15N'!F28 -> 7.6754946e-07 | K19: ='ISIRF 15N'!G28 -> 0.0036685582 | L19: ='ISIRF 15N'!H28 -> 2
A20: Replicate Sample 2 | C20: ='Investigator Data'!B17 -> 20240407_E2_D | E20: ='ISIRF 15N'!B29 -> 7.3373171 | F20: ='ISIRF 15N'!C29 -> 0.023252801 | G20: ='ISIRF 15N'!D29 -> 0.15248869 | I20: ='ISIRF 15N'!E29 -> 0.33263131 | J20: ='ISIRF 15N'!F29 -> 0.00012802244 | K20: ='ISIRF 15N'!G29 -> 0.03401574 | L20: ='ISIRF 15N'!H29 -> 2
A22: Quality Assurance Data for Sulfur: | E22: d34S | I22: %S | M22: Precision of Sulfur data
C23: Sample | D23: Actual | E23: Meas. | F23: Var. | G23: s.d. | H23: Actual | I23: Meas. | J23: Var. | K23: s.d. | L23: N | M23: d34S | O23: =IF(SUM(L25:L29)<2,"",SQRT(SUMPRODUCT(F24:F29,L24:L29)/SUM(L24:L29)))
A24: NIST Certified Isotope Standard - QC | M24: [S] % | O24: =IF(SUM(L25:L29)<2,"",SQRT(SUMPRODUCT(J24:J29,L24:L29)/SUM(L24:L29)))
A25: Conc Cal Std - Isotope QC Std | M25: Accuracy of Sulfur data
A26: Conc QC Std - Isotope High Cal Std | M26: d34S | O26: =IF(COUNT(E24:E25)=0,"",D24-E24)
A27: Conc QC Std - Isotope Low Cal Std | M27: [S] % | O27: =IF(COUNT(I24,I26:I27)=0,"",AVERAGE(H24-I24,H26-I26,H27-I27))
A28: Replicate Sample 1
A29: Replicate Sample 2
A31: Standard and replicate data
A32: Run date | B32: File name | D32: Standard | E32: Run type | F32: Seq # | G32: Wt. (mg) | H32: Mass 28 nAmp | I32: Mass 28 Area | J32: %N | K32: δ15N | L32: Mass 44 nAmp | M32: Mass 44 Area | N32: %C | O32: δ13C | Q32: Notes
A33: ='ISIRF RAW'!$B$2 -> 44278 | B33: ='ISIRF 15N'!B11 -> IC15N-241218-10KansasRoarCarbon-3_3.raw | D33: ='ISIRF 15N'!D11 -> ISIRF Ulva | E33: ='ISIRF 15N'!E11 -> QC.STD | F33: ='ISIRF 15N'!F11 -> 9 | G33: ='ISIRF 15N'!G11 -> 1.203 | H33: ='ISIRF 15N'!H11 -> 4.4609385 | I33: ='ISIRF 15N'!I11 -> 71002552 | J33: ='ISIRF 15N'!J11 -> 4.1283299 | K33: ='ISIRF 15N'!K11 -> 7.5012053 | L33: ='ISIRF 13C'!H11 -> 5.5944675 | M33: ='ISIRF 13C'!I11 -> 56886720 | N33: ='ISIRF 13C'!J11 -> 32.893523 | O33: ='ISIRF 13C'!K11 -> -12.789826 | P33: ='ISIRF 15N'!L11&'ISIRF 13C'!L11 | R33: =IF(COUNTA('ISIRF 15N'!L11)=1,"See ISIRF 15N","")
A34: ='ISIRF RAW'!$B$2 -> 44278 | B34: ='ISIRF 15N'!B12 -> IC15N-241218-10KansasRoarCarbon-3_16.raw | D34: ='ISIRF 15N'!D12 -> ISIRF Ulva | E34: ='ISIRF 15N'!E12 -> QC.STD | F34: ='ISIRF 15N'!F12 -> 22 | G34: ='ISIRF 15N'!G12 -> 1.163 | H34: ='ISIRF 15N'!H12 -> 4.3527875 | I34: ='ISIRF 15N'!I12 -> 68136512 | J34: ='ISIRF 15N'!J12 -> 4.0754844 | K34: ='ISIRF 15N'!K12 -> 7.6583516 | L34: ='ISIRF 13C'!H12 -> 5.2944795 | M34: ='ISIRF 13C'!I12 -> 54060448 | N34: ='ISIRF 13C'!J12 -> 32.671622 | O34: ='ISIRF 13C'!K12 -> -12.929753 | P34: ='ISIRF 15N'!L12&'ISIRF 13C'!L12 | R34: =IF(COUNTA('ISIRF 15N'!L12)=1,"See ISIRF 15N","")
A35: ='ISIRF RAW'!$B$2 -> 44278 | B35: ='ISIRF 15N'!B13 -> IC15N-241218-10KansasRoarCarbon-3_28.raw | D35: ='ISIRF 15N'!D13 -> ISIRF Ulva | E35: ='ISIRF 15N'!E13 -> QC.STD | F35: ='ISIRF 15N'!F13 -> 34 | G35: ='ISIRF 15N'!G13 -> 1.135 | H35: ='ISIRF 15N'!H13 -> 4.2833895 | I35: ='ISIRF 15N'!I13 -> 68224672 | J35: ='ISIRF 15N'!J13 -> 4.4116143 | K35: ='ISIRF 15N'!K13 -> 7.4609602 | L35: ='ISIRF 13C'!H13 -> 5.3408835 | M35: ='ISIRF 13C'!I13 -> 54826460 | N35: ='ISIRF 13C'!J13 -> 33.803227 | O35: ='ISIRF 13C'!K13 -> -13.069165 | P35: ='ISIRF 15N'!L13&'ISIRF 13C'!L13 | R35: =IF(COUNTA('ISIRF 15N'!L13)=1,"See ISIRF 15N","")
A36: ='ISIRF RAW'!$B$2 -> 44278 | B36: ='ISIRF 15N'!B14 -> IC15N-241218-10KansasRoarCarbon-3_41.raw | D36: ='ISIRF 15N'!D14 -> ISIRF Ulva | E36: ='ISIRF 15N'!E14 -> QC.STD | F36: ='ISIRF 15N'!F14 -> 47 | G36: ='ISIRF 15N'!G14 -> 1.243 | H36: ='ISIRF 15N'!H14 -> 4.7837185 | I36: ='ISIRF 15N'!I14 -> 75677504 | J36: ='ISIRF 15N'!J14 -> 4.5748715 | K36: ='ISIRF 15N'!K14 -> 7.6112382 | L36: ='ISIRF 13C'!H14 -> 5.9749665 | M36: ='ISIRF 13C'!I14 -> 62196408 | N36: ='ISIRF 13C'!J14 -> 34.947143 | O36: ='ISIRF 13C'!K14 -> -12.980982 | P36: ='ISIRF 15N'!L14&'ISIRF 13C'!L14 | R36: =IF(COUNTA('ISIRF 15N'!L14)=1,"See ISIRF 15N","")
A37: ='ISIRF RAW'!$B$2 -> 44278 | B37: ='ISIRF 15N'!B15 -> IC15N-241218-10KansasRoarCarbon-3_53.raw | D37: ='ISIRF 15N'!D15 -> ISIRF Ulva | E37: ='ISIRF 15N'!E15 -> QC.STD | F37: ='ISIRF 15N'!F15 -> 59 | G37: ='ISIRF 15N'!G15 -> 1.284 | H37: ='ISIRF 15N'!H15 -> 4.7322405 | I37: ='ISIRF 15N'!I15 -> 75844800 | J37: ='ISIRF 15N'!J15 -> 4.2046409 | K37: ='ISIRF 15N'!K15 -> 7.3708843 | L37: ='ISIRF 13C'!H15 -> 6.0247025 | M37: ='ISIRF 13C'!I15 -> 61022608 | N37: ='ISIRF 13C'!J15 -> 33.231979 | O37: ='ISIRF 13C'!K15 -> -12.675693 | P37: ='ISIRF 15N'!L15&'ISIRF 13C'!L15 | R37: =IF(COUNTA('ISIRF 15N'!L15)=1,"See ISIRF 15N","")
A38: ='ISIRF RAW'!$B$2 -> 44278 | B38: ='ISIRF 15N'!B16 -> IC15N-241218-10KansasRoarCarbon-3_4.raw | D38: ='ISIRF 15N'!D16 -> ISIRF Chitin | E38: ='ISIRF 15N'!E16 -> Cal-H.STD | F38: ='ISIRF 15N'!F16 -> 10 | G38: ='ISIRF 15N'!G16 -> 0.963 | H38: ='ISIRF 15N'!H16 -> 5.6857765 | I38: ='ISIRF 15N'!I16 -> 89403248 | J38: ='ISIRF 15N'!J16 -> 6.4136891 | K38: ='ISIRF 15N'!K16 -> -4.9198917 | L38: ='ISIRF 13C'!H16 -> 6.131893 | M38: ='ISIRF 13C'!H16 -> 6.131893 | N38: ='ISIRF 13C'!J16 -> 45.407268 | O38: ='ISIRF 13C'!K16 -> -21.327304
A39: ='ISIRF RAW'!$B$2 -> 44278 | B39: ='ISIRF 15N'!B17 -> IC15N-241218-10KansasRoarCarbon-3_29.raw | D39: ='ISIRF 15N'!D17 -> ISIRF Chitin | E39: ='ISIRF 15N'!E17 -> Cal-H.STD | F39: ='ISIRF 15N'!F17 -> 35 | G39: ='ISIRF 15N'!G17 -> 0.979 | H39: ='ISIRF 15N'!H17 -> 5.7937785 | I39: ='ISIRF 15N'!I17 -> 90953440 | J39: ='ISIRF 15N'!J17 -> 6.5966563 | K39: ='ISIRF 15N'!K17 -> -4.9643394 | L39: ='ISIRF 13C'!H17 -> 6.4089935 | M39: ='ISIRF 13C'!I17 -> 65508340 | N39: ='ISIRF 13C'!J17 -> 46.722905 | O39: ='ISIRF 13C'!K17 -> -21.077763
A40: ='ISIRF RAW'!$B$2 -> 44278 | B40: ='ISIRF 15N'!B18 -> IC15N-241218-10KansasRoarCarbon-3_54.raw | D40: ='ISIRF 15N'!D18 -> ISIRF Chitin | E40: ='ISIRF 15N'!E18 -> Cal-H.STD | F40: ='ISIRF 15N'!F18 -> 60 | G40: ='ISIRF 15N'!G18 -> 1.079 | H40: ='ISIRF 15N'!H18 -> 6.3247525 | I40: ='ISIRF 15N'!I18 -> 100359056 | J40: ='ISIRF 15N'!J18 -> 6.5334226 | K40: ='ISIRF 15N'!K18 -> -5.0483298 | L40: ='ISIRF 13C'!H18 -> 6.968069 | M40: ='ISIRF 13C'!I18 -> 71153696 | N40: ='ISIRF 13C'!J18 -> 46.017995 | O40: ='ISIRF 13C'!K18 -> -21.228962
A41: ='ISIRF RAW'!$B$2 -> 44278 | B41: ='ISIRF 15N'!B19 -> IC15N-241218-10KansasRoarCarbon-3_5.raw | D41: ='ISIRF 15N'!D19 -> ISIRF Bamboo | E41: ='ISIRF 15N'!E19 -> Cal-L.STD | F41: ='ISIRF 15N'!F19 -> 11 | G41: ='ISIRF 15N'!G19 -> 1.446 | H41: ='ISIRF 15N'!H19 -> 3.8349592 | I41: ='ISIRF 15N'!I19 -> 61901156 | J41: ='ISIRF 15N'!J19 -> 3.0516232 | K41: ='ISIRF 15N'!K19 -> 1.9277698 | L41: ='ISIRF 13C'!H19 -> 8.791895 | M41: ='ISIRF 13C'!I19 -> 92055536 | N41: ='ISIRF 13C'!J19 -> 44.225859 | O41: ='ISIRF 13C'!K19 -> -30.404534
A42: ='ISIRF RAW'!$B$2 -> 44278 | B42: ='ISIRF 15N'!B20 -> IC15N-241218-10KansasRoarCarbon-3_30.raw | D42: ='ISIRF 15N'!D20 -> ISIRF Bamboo | E42: ='ISIRF 15N'!E20 -> Cal-L.STD | F42: ='ISIRF 15N'!F20 -> 36 | G42: ='ISIRF 15N'!G20 -> 1.621 | H42: ='ISIRF 15N'!H20 -> 4.379383 | I42: ='ISIRF 15N'!I20 -> 70220600 | J42: ='ISIRF 15N'!J20 -> 3.1511853 | K42: ='ISIRF 15N'!K20 -> 2.0151128 | L42: ='ISIRF 13C'!H20 -> 10.065845 | M42: ='ISIRF 13C'!I20 -> 105692624 | N42: ='ISIRF 13C'!J20 -> 45.379005 | O42: ='ISIRF 13C'!K20 -> -30.173958
A43: ='ISIRF RAW'!$B$2 -> 44278 | B43: ='ISIRF 15N'!B21 -> IC15N-241218-10KansasRoarCarbon-3_55.raw | D43: ='ISIRF 15N'!D21 -> ISIRF Bamboo | E43: ='ISIRF 15N'!E21 -> Cal-L.STD | F43: ='ISIRF 15N'!F21 -> 61 | G43: ='ISIRF 15N'!G21 -> 1.581 | H43: ='ISIRF 15N'!H21 -> 4.0268023 | I43: ='ISIRF 15N'!I21 -> 65638524 | J43: ='ISIRF 15N'!J21 -> 3.0391939 | K43: ='ISIRF 15N'!K21 -> 2.0619767 | L43: ='ISIRF 13C'!H21 -> 9.496792 | M43: ='ISIRF 13C'!I21 -> 98699496 | N43: ='ISIRF 13C'!J21 -> 43.490597 | O43: ='ISIRF 13C'!K21 -> -30.272725
A44: ='ISIRF RAW'!$B$2 -> 44278 | B44: ='ISIRF 15N'!B22 -> IC15N-241218-10KansasRoarCarbon-3_6.raw | D44: ='ISIRF 15N'!D22 -> NBS 1575 Pine Needles | E44: ='ISIRF 15N'!E22 -> QA STD | F44: ='ISIRF 15N'!F22 -> 12 | G44: ='ISIRF 15N'!G22 -> 6.792 | H44: ='ISIRF 15N'!H22 -> 6.4396345 | I44: ='ISIRF 15N'!I22 -> 112044144 | J44: ='ISIRF 15N'!J22 -> 1.2213563 | K44: ='ISIRF 15N'!K22 -> 0.60130857 | L44: ='ISIRF 13C'!H22 -> 34.312516 | M44: ='ISIRF 13C'!I22 -> 500603232 | N44: ='ISIRF 13C'!J22 -> 51.545291 | O44: ='ISIRF 13C'!K22 -> -25.817906
A45: ='ISIRF RAW'!$B$2 -> 44278 | B45: ='ISIRF 15N'!B23 -> IC15N-241218-10KansasRoarCarbon-3_31.raw | D45: ='ISIRF 15N'!D23 -> NBS 1575 Pine Needles | E45: ='ISIRF 15N'!E23 -> QA STD | F45: ='ISIRF 15N'!F23 -> 37 | G45: ='ISIRF 15N'!G23 -> 6.574 | H45: ='ISIRF 15N'!H23 -> 6.2617775 | I45: ='ISIRF 15N'!I23 -> 111667816 | J45: ='ISIRF 15N'!J23 -> 1.2837462 | K45: ='ISIRF 15N'!K23 -> 0.34811246 | L45: ='ISIRF 13C'!H23 -> 34.086204 | M45: ='ISIRF 13C'!I23 -> 485313664 | N45: ='ISIRF 13C'!J23 -> 51.494598 | O45: ='ISIRF 13C'!K23 -> -25.888578
...

Sheet ISIRF 15N
A1: FILE NAME: | B1: =COVER!C2 -> IC13C-241218-10KansasROARCarbon-3
A3: Standard | B3: Run Type | C3: δ15N | D3: %N
A4: ='Weigh Sheet'!C9 -> ISIRF Ulva | B4: QC.STD | C4: ='ISIRF RAW'!C63 -> 7.4989403 | D4: ='ISIRF RAW'!D63 -> 4.2927354
A5: ='Weigh Sheet'!C10 -> ISIRF Chitin | B5: Cal-H.STD | C5: ='ISIRF RAW'!C64 -> -5.0093785 | D5: ='ISIRF RAW'!D64 -> 6.5259675
A6: ='Weigh Sheet'!C11 -> ISIRF Bamboo | B6: Cal-L.STD | C6: ='ISIRF RAW'!C65 -> 2.0694573 | D6: ='ISIRF RAW'!D65 -> 3.0463773
A7: ='Weigh Sheet'!C12 -> NBS 1575 Pine Needles | B7: Check QC | C7: ='ISIRF RAW'!C66 -> 0.36348603 | D7: ='ISIRF RAW'!D66 -> 1.1397949
A9: Nitrogen Standards
A10: Run date | B10: File name | D10: Standard | E10: Run type | F10: Seq # | G10: Wt. (mg) | H10: Mass 28 nAmp | I10: N2 Area | J10: %N | K10: δ15N | L10: Notes
A11: ='ISIRF RAW'!S8 -> 45740.703 | B11: ='ISIRF RAW'!T8 -> IC15N-241218-10KansasRoarCarbon-3_3.raw | D11: ='ISIRF RAW'!A8 -> ISIRF Ulva | E11: =$B$4 -> QC.STD | F11: ='ISIRF RAW'!B8 -> 9 | G11: ='ISIRF RAW'!C8 -> 1.203 | H11: ='ISIRF RAW'!D8 -> 4.4609385 | I11: ='ISIRF RAW'!E8 -> 71002552 | J11: ='ISIRF RAW'!J8 -> 4.1283299 | K11: ='ISIRF RAW'!L8 -> 7.5012053
A12: ='ISIRF RAW'!S21 -> 45740.806 | B12: ='ISIRF RAW'!T21 -> IC15N-241218-10KansasRoarCarbon-3_16.raw | D12: ='ISIRF RAW'!A21 -> ISIRF Ulva | E12: =$B$4 -> QC.STD | F12: ='ISIRF RAW'!B21 -> 22 | G12: ='ISIRF RAW'!C21 -> 1.163 | H12: ='ISIRF RAW'!D21 -> 4.3527875 | I12: ='ISIRF RAW'!E21 -> 68136512 | J12: ='ISIRF RAW'!J21 -> 4.0754844 | K12: ='ISIRF RAW'!L21 -> 7.6583516
A13: ='ISIRF RAW'!S33 -> 45740.9 | B13: ='ISIRF RAW'!T33 -> IC15N-241218-10KansasRoarCarbon-3_28.raw | D13: ='ISIRF RAW'!A33 -> ISIRF Ulva | E13: =$B$4 -> QC.STD | F13: ='ISIRF RAW'!B33 -> 34 | G13: ='ISIRF RAW'!C33 -> 1.135 | H13: ='ISIRF RAW'!D33 -> 4.2833895 | I13: ='ISIRF RAW'!E33 -> 68224672 | J13: ='ISIRF RAW'!J33 -> 4.4116143 | K13: ='ISIRF RAW'!L33 -> 7.4609602
A14: ='ISIRF RAW'!S46 -> 45741.002 | B14: ='ISIRF RAW'!T46 -> IC15N-241218-10KansasRoarCarbon-3_41.raw | D14: ='ISIRF RAW'!A46 -> ISIRF Ulva | E14: =$B$4 -> QC.STD | F14: ='ISIRF RAW'!B46 -> 47 | G14: ='ISIRF RAW'!C46 -> 1.243 | H14: ='ISIRF RAW'!D46 -> 4.7837185 | I14: ='ISIRF RAW'!E46 -> 75677504 | J14: ='ISIRF RAW'!J46 -> 4.5748715 | K14: ='ISIRF RAW'!L46 -> 7.6112382
A15: ='ISIRF RAW'!S58 -> 45741.096 | B15: ='ISIRF RAW'!T58 -> IC15N-241218-10KansasRoarCarbon-3_53.raw | D15: ='ISIRF RAW'!A58 -> ISIRF Ulva | E15: =$B$4 -> QC.STD | F15: ='ISIRF RAW'!B58 -> 59 | G15: ='ISIRF RAW'!C58 -> 1.284 | H15: ='ISIRF RAW'!D58 -> 4.7322405 | I15: ='ISIRF RAW'!E58 -> 75844800 | J15: ='ISIRF RAW'!J58 -> 4.2046409 | K15: ='ISIRF RAW'!L58 -> 7.3708843
A16: ='ISIRF RAW'!S9 -> 45740.711 | B16: ='ISIRF RAW'!T9 -> IC15N-241218-10KansasRoarCarbon-3_4.raw | D16: ='ISIRF RAW'!A9 -> ISIRF Chitin | E16: =B$5 -> Cal-H.STD | F16: ='ISIRF RAW'!B9 -> 10 | G16: ='ISIRF RAW'!C9 -> 0.963 | H16: ='ISIRF RAW'!D9 -> 5.6857765 | I16: ='ISIRF RAW'!E9 -> 89403248 | J16: ='ISIRF RAW'!J9 -> 6.4136891 | K16: ='ISIRF RAW'!L9 -> -4.9198917
A17: ='ISIRF RAW'!S34 -> 45740.908 | B17: ='ISIRF RAW'!T34 -> IC15N-241218-10KansasRoarCarbon-3_29.raw | D17: ='ISIRF RAW'!A34 -> ISIRF Chitin | E17: =B$5 -> Cal-H.STD | F17: ='ISIRF RAW'!B34 -> 35 | G17: ='ISIRF RAW'!C34 -> 0.979 | H17: ='ISIRF RAW'!D34 -> 5.7937785 | I17: ='ISIRF RAW'!E34 -> 90953440 | J17: ='ISIRF RAW'!J34 -> 6.5966563 | K17: ='ISIRF RAW'!L34 -> -4.9643394
A18: ='ISIRF RAW'!S59 -> 45741.104 | B18: ='ISIRF RAW'!T59 -> IC15N-241218-10KansasRoarCarbon-3_54.raw | D18: ='ISIRF RAW'!A59 -> ISIRF Chitin | E18: =B$5 -> Cal-H.STD | F18: ='ISIRF RAW'!B59 -> 60 | G18: ='ISIRF RAW'!C59 -> 1.079 | H18: ='ISIRF RAW'!D59 -> 6.3247525 | I18: ='ISIRF RAW'!E59 -> 100359056 | J18: ='ISIRF RAW'!J59 -> 6.5334226 | K18: ='ISIRF RAW'!L59 -> -5.0483298
A19: ='ISIRF RAW'!S10 -> 45740.719 | B19: ='ISIRF RAW'!T10 -> IC15N-241218-10KansasRoarCarbon-3_5.raw | D19: ='ISIRF RAW'!A10 -> ISIRF Bamboo | E19: =B$6 -> Cal-L.STD | F19: ='ISIRF RAW'!B10 -> 11 | G19: ='ISIRF RAW'!C10 -> 1.446 | H19: ='ISIRF RAW'!D10 -> 3.8349592 | I19: ='ISIRF RAW'!E10 -> 61901156 | J19: ='ISIRF RAW'!J10 -> 3.0516232 | K19: ='ISIRF RAW'!L10 -> 1.9277698
A20: ='ISIRF RAW'!S35 -> 45740.916 | B20: ='ISIRF RAW'!T35 -> IC15N-241218-10KansasRoarCarbon-3_30.raw | D20: ='ISIRF RAW'!A35 -> ISIRF Bamboo | E20: =B$6 -> Cal-L.STD | F20: ='ISIRF RAW'!B35 -> 36 | G20: ='ISIRF RAW'!C35 -> 1.621 | H20: ='ISIRF RAW'!D35 -> 4.379383 | I20: ='ISIRF RAW'!E35 -> 70220600 | J20: ='ISIRF RAW'!J35 -> 3.1511853 | K20: ='ISIRF RAW'!L35 -> 2.0151128
A21: ='ISIRF RAW'!S60 -> 45741.112 | B21: ='ISIRF RAW'!T60 -> IC15N-241218-10KansasRoarCarbon-3_55.raw | D21: ='ISIRF RAW'!A60 -> ISIRF Bamboo | E21: =B$6 -> Cal-L.STD | F21: ='ISIRF RAW'!B60 -> 61 | G21: ='ISIRF RAW'!C60 -> 1.581 | H21: ='ISIRF RAW'!D60 -> 4.0268023 | I21: ='ISIRF RAW'!E60 -> 65638524 | J21: ='ISIRF RAW'!J60 -> 3.0391939 | K21: ='ISIRF RAW'!L60 -> 2.0619767
A22: ='ISIRF RAW'!S11 -> 45740.727 | B22: ='ISIRF RAW'!T11 -> IC15N-241218-10KansasRoarCarbon-3_6.raw | D22: ='ISIRF RAW'!A11 -> NBS 1575 Pine Needles | E22: QA STD | F22: ='ISIRF RAW'!B11 -> 12 | G22: ='ISIRF RAW'!C11 -> 6.792 | H22: ='ISIRF RAW'!D11 -> 6.4396345 | I22: ='ISIRF RAW'!E11 -> 112044144 | J22: ='ISIRF RAW'!J11 -> 1.2213563 | K22: ='ISIRF RAW'!L11 -> 0.60130857
A23: ='ISIRF RAW'!S36 -> 45740.923 | B23: ='ISIRF RAW'!T36 -> IC15N-241218-10KansasRoarCarbon-3_31.raw | D23: ='ISIRF RAW'!A36 -> NBS 1575 Pine Needles | E23: QA STD | F23: ='ISIRF RAW'!B36 -> 37 | G23: ='ISIRF RAW'!C36 -> 6.574 | H23: ='ISIRF RAW'!D36 -> 6.2617775 | I23: ='ISIRF RAW'!E36 -> 111667816 | J23: ='ISIRF RAW'!J36 -> 1.2837462 | K23: ='ISIRF RAW'!L36 -> 0.34811246
A24: ='ISIRF RAW'!S61 -> 45741.12 | B24: ='ISIRF RAW'!T61 -> IC15N-241218-10KansasRoarCarbon-3_56.raw | D24: ='ISIRF RAW'!A61 -> NBS 1575 Pine Needles | E24: QA STD | F24: ='ISIRF RAW'!B61 -> 62 | G24: ='ISIRF RAW'!C61 -> 6.873 | H24: ='ISIRF RAW'!D61 -> 6.4289025 | I24: ='ISIRF RAW'!E61 -> 117563456 | J24: ='ISIRF RAW'!J61 -> 1.2808622 | K24: ='ISIRF RAW'!L61 -> 0.45674064
A26: QA Summary 15N: | C26: d15N | F26: %N | H26: N
B27: X | C27: var. | D27: s.d. | E27: X | F27: var | G27: r.s.d.
A28: REP1 (‰) | B28: =AVERAGE('ISIRF RAW'!L12,'ISIRF RAW'!L56) -> 6.0309836 | C28: =VAR('ISIRF RAW'!L12,'ISIRF RAW'!L56) -> 0.050163256 | D28: =STDEV('ISIRF RAW'!L12,'ISIRF RAW'!L56) -> 0.22397155 | E28: =AVERAGE('ISIRF RAW'!J12,'ISIRF RAW'!J56) -> 0.23881289 | F28: =VAR('ISIRF RAW'!J12,'ISIRF RAW'!J56) -> 7.6754946e-07 | G28: =(STDEV('ISIRF RAW'!J12,'ISIRF RAW'!J56))/E28 -> 0.0036685582 | H28: =COUNT('ISIRF RAW'!J12,'ISIRF RAW'!J56) -> 2
A29: REP2 (‰) | B29: =AVERAGE('ISIRF RAW'!L26:L27) -> 7.3373171 | C29: =VAR('ISIRF RAW'!L26:L27) -> 0.023252801 | D29: =STDEV('ISIRF RAW'!L26:L27) -> 0.15248869 | E29: =AVERAGE('ISIRF RAW'!J26:J27) -> 0.33263131 | F29: =VAR('ISIRF RAW'!J26:J27) -> 0.00012802244 | G29: =(STDEV('ISIRF RAW'!J26:J27))/E29 -> 0.03401574 | H29: =COUNT('ISIRF RAW'!J26:J27) -> 2
A30: =B4 -> QC.STD | B30: =AVERAGE(K11:K15) -> 7.5205279 | C30: =VAR(K11:K15) -> 0.013384648 | D30: =STDEV(K11:K15) -> 0.11569204 | E30: =AVERAGE(J11:J15) -> 4.2789882 | F30: =VAR(J11:J15) -> 0.043693963 | G30: =(STDEV(J11:J15))/E30 -> 0.04885057 | H30: =COUNT(J11:J15) -> 5
A31: =B5 -> Cal-H.STD | B31: =AVERAGE(K16:K18) -> -4.9775203 | C31: =VAR(K16:K18) -> 0.0042543877 | D31: =STDEV(K16:K18) -> 0.065225668 | E31: =AVERAGE(J16:J18) -> 6.5145893 | F31: =VAR(J16:J18) -> 0.0086352642 | G31: =(STDEV(J16:J18))/E31 -> 0.01426431 | H31: =COUNT(J16:J18) -> 3
A32: =B6 -> Cal-L.STD | B32: =AVERAGE(K19:K21) -> 2.0016198 | C32: =VAR(K19:K21) -> 0.0046394184 | D32: =STDEV(K19:K21) -> 0.068113276 | E32: =AVERAGE(J19:J21) -> 3.0806675 | F32: =VAR(J19:J21) -> 0.0037681967 | G32: =(STDEV(J19:J21))/E32 -> 0.019926084 | H32: =COUNT(J19:J21) -> 3
A33: =B7 -> Check QC | B33: =AVERAGE(K22:K24) -> 0.46872056 | C33: =VAR(K22:K24) -> 0.016134707 | D33: =STDEV(K22:K24) -> 0.12702247 | E33: =AVERAGE(J22:J24) -> 1.2619882 | F33: =VAR(J22:J24) -> 0.0012402948 | G33: =(STDEV(J22:J24))/E33 -> 0.027906615 | H33: =COUNT(J22:J24) -> 3
B34: Notes:

Sheet ISIRF 13C
A1: FILE NAME: | B1: =COVER!C2 -> IC13C-241218-10KansasROARCarbon-3
A3: Standard | B3: Run Type | C3: Actual d13C | D3: %C
A4: ='Weigh Sheet'!C9 -> ISIRF Ulva | B4: QC.STD | C4: ='ISIRF RAW'!E63 -> -12.890511 | D4: ='ISIRF RAW'!F63 -> 33.294438
A5: ='Weigh Sheet'!C10 -> ISIRF Chitin | B5: Cal-H.STD | C5: ='ISIRF RAW'!E64 -> -21.201039 | D5: ='ISIRF RAW'!F64 -> 44.925159
A6: ='Weigh Sheet'!C11 -> ISIRF Bamboo | B6: Cal-L.STD | C6: ='ISIRF RAW'!E65 -> -30.291664 | D6: ='ISIRF RAW'!F65 -> 45.850178
A7: ='Weigh Sheet'!C12 -> NBS 1575 Pine Needles | B7: Check QC | C7: ='ISIRF RAW'!E66 -> -25.808178 | D7: ='ISIRF RAW'!F66 -> 52.254104
A9: Carbon Standards
A10: Run date | B10: File name | D10: Standard | E10: Run type | F10: Seq # | G10: Wt. (mg) | H10: Mass 44 nAmp | I10: CO2 Area | J10: %C | K10: δ13C | L10: Notes
A11: ='ISIRF RAW'!S8 -> 45740.703 | B11: ='ISIRF RAW'!T8 -> IC15N-241218-10KansasRoarCarbon-3_3.raw | D11: ='ISIRF RAW'!A8 -> ISIRF Ulva | E11: QC.STD | F11: ='ISIRF RAW'!B8 -> 9 | G11: ='ISIRF RAW'!C8 -> 1.203 | H11: ='ISIRF RAW'!F8 -> 5.5944675 | I11: ='ISIRF RAW'!G8 -> 56886720 | J11: ='ISIRF RAW'!M8 -> 32.893523 | K11: ='ISIRF RAW'!O8 -> -12.789826
A12: ='ISIRF RAW'!S21 -> 45740.806 | B12: ='ISIRF RAW'!T21 -> IC15N-241218-10KansasRoarCarbon-3_16.raw | D12: ='ISIRF RAW'!A21 -> ISIRF Ulva | E12: QC.STD | F12: ='ISIRF RAW'!B21 -> 22 | G12: ='ISIRF RAW'!C21 -> 1.163 | H12: ='ISIRF RAW'!F21 -> 5.2944795 | I12: ='ISIRF RAW'!G21 -> 54060448 | J12: ='ISIRF RAW'!M21 -> 32.671622 | K12: ='ISIRF RAW'!O21 -> -12.929753
A13: ='ISIRF RAW'!S33 -> 45740.9 | B13: ='ISIRF RAW'!T33 -> IC15N-241218-10KansasRoarCarbon-3_28.raw | D13: ='ISIRF RAW'!A33 -> ISIRF Ulva | E13: QC.STD | F13: ='ISIRF RAW'!B33 -> 34 | G13: ='ISIRF RAW'!C33 -> 1.135 | H13: ='ISIRF RAW'!F33 -> 5.3408835 | I13: ='ISIRF RAW'!G33 -> 54826460 | J13: ='ISIRF RAW'!M33 -> 33.803227 | K13: ='ISIRF RAW'!O33 -> -13.069165
A14: ='ISIRF RAW'!S46 -> 45741.002 | B14: ='ISIRF RAW'!T46 -> IC15N-241218-10KansasRoarCarbon-3_41.raw | D14: ='ISIRF RAW'!A46 -> ISIRF Ulva | E14: QC.STD | F14: ='ISIRF RAW'!B46 -> 47 | G14: ='ISIRF RAW'!C46 -> 1.243 | H14: ='ISIRF RAW'!F46 -> 5.9749665 | I14: ='ISIRF RAW'!G46 -> 62196408 | J14: ='ISIRF RAW'!M46 -> 34.947143 | K14: ='ISIRF RAW'!O46 -> -12.980982
A15: ='ISIRF RAW'!S58 -> 45741.096 | B15: ='ISIRF RAW'!T58 -> IC15N-241218-10KansasRoarCarbon-3_53.raw | D15: ='ISIRF RAW'!A58 -> ISIRF Ulva | E15: QC.STD | F15: ='ISIRF RAW'!B58 -> 59 | G15: ='ISIRF RAW'!C58 -> 1.284 | H15: ='ISIRF RAW'!F58 -> 6.0247025 | I15: ='ISIRF RAW'!G58 -> 61022608 | J15: ='ISIRF RAW'!M58 -> 33.231979 | K15: ='ISIRF RAW'!O58 -> -12.675693
A16: ='ISIRF RAW'!S9 -> 45740.711 | B16: ='ISIRF RAW'!T9 -> IC15N-241218-10KansasRoarCarbon-3_4.raw | D16: ='ISIRF RAW'!A9 -> ISIRF Chitin | E16: Cal-H.STD | F16: ='ISIRF RAW'!B9 -> 10 | G16: ='ISIRF RAW'!C9 -> 0.963 | H16: ='ISIRF RAW'!F9 -> 6.131893 | I16: ='ISIRF RAW'!G9 -> 62863428 | J16: ='ISIRF RAW'!M9 -> 45.407268 | K16: ='ISIRF RAW'!O9 -> -21.327304
A17: ='ISIRF RAW'!S34 -> 45740.908 | B17: ='ISIRF RAW'!T34 -> IC15N-241218-10KansasRoarCarbon-3_29.raw | D17: ='ISIRF RAW'!A34 -> ISIRF Chitin | E17: Cal-H.STD | F17: ='ISIRF RAW'!B34 -> 35 | G17: ='ISIRF RAW'!C34 -> 0.979 | H17: ='ISIRF RAW'!F34 -> 6.4089935 | I17: ='ISIRF RAW'!G34 -> 65508340 | J17: ='ISIRF RAW'!M34 -> 46.722905 | K17: ='ISIRF RAW'!O34 -> -21.077763
A18: ='ISIRF RAW'!S59 -> 45741.104 | B18: ='ISIRF RAW'!T59 -> IC15N-241218-10KansasRoarCarbon-3_54.raw | D18: ='ISIRF RAW'!A59 -> ISIRF Chitin | E18: Cal-H.STD | F18: ='ISIRF RAW'!B59 -> 60 | G18: ='ISIRF RAW'!C59 -> 1.079 | H18: ='ISIRF RAW'!F59 -> 6.968069 | I18: ='ISIRF RAW'!G59 -> 71153696 | J18: ='ISIRF RAW'!M59 -> 46.017995 | K18: ='ISIRF RAW'!O59 -> -21.228962
A19: ='ISIRF RAW'!S10 -> 45740.719 | B19: ='ISIRF RAW'!T10 -> IC15N-241218-10KansasRoarCarbon-3_5.raw | D19: ='ISIRF RAW'!A10 -> ISIRF Bamboo | E19: Cal-L.STD | F19: ='ISIRF RAW'!B10 -> 11 | G19: ='ISIRF RAW'!C10 -> 1.446 | H19: ='ISIRF RAW'!F10 -> 8.791895 | I19: ='ISIRF RAW'!G10 -> 92055536 | J19: ='ISIRF RAW'!M10 -> 44.225859 | K19: ='ISIRF RAW'!O10 -> -30.404534
A20: ='ISIRF RAW'!S35 -> 45740.916 | B20: ='ISIRF RAW'!T35 -> IC15N-241218-10KansasRoarCarbon-3_30.raw | D20: ='ISIRF RAW'!A35 -> ISIRF Bamboo | E20: Cal-L.STD | F20: ='ISIRF RAW'!B35 -> 36 | G20: ='ISIRF RAW'!C35 -> 1.621 | H20: ='ISIRF RAW'!F35 -> 10.065845 | I20: ='ISIRF RAW'!G35 -> 105692624 | J20: ='ISIRF RAW'!M35 -> 45.379005 | K20: ='ISIRF RAW'!O35 -> -30.173958
A21: ='ISIRF RAW'!S60 -> 45741.112 | B21: ='ISIRF RAW'!T60 -> IC15N-241218-10KansasRoarCarbon-3_55.raw | D21: ='ISIRF RAW'!A60 -> ISIRF Bamboo | E21: Cal-L.STD | F21: ='ISIRF RAW'!B60 -> 61 | G21: ='ISIRF RAW'!C60 -> 1.581 | H21: ='ISIRF RAW'!F60 -> 9.496792 | I21: ='ISIRF RAW'!G60 -> 98699496 | J21: ='ISIRF RAW'!M60 -> 43.490597 | K21: ='ISIRF RAW'!O60 -> -30.272725
A22: ='ISIRF RAW'!S11 -> 45740.727 | B22: ='ISIRF RAW'!T11 -> IC15N-241218-10KansasRoarCarbon-3_6.raw | D22: ='ISIRF RAW'!A11 -> NBS 1575 Pine Needles | E22: Cal-L.STD | F22: ='ISIRF RAW'!B11 -> 12 | G22: ='ISIRF RAW'!C11 -> 6.792 | H22: ='ISIRF RAW'!F11 -> 34.312516 | I22: ='ISIRF RAW'!G11 -> 500603232 | J22: ='ISIRF RAW'!M11 -> 51.545291 | K22: ='ISIRF RAW'!O11 -> -25.817906
A23: ='ISIRF RAW'!S36 -> 45740.923 | B23: ='ISIRF RAW'!T36 -> IC15N-241218-10KansasRoarCarbon-3_31.raw | D23: ='ISIRF RAW'!A36 -> NBS 1575 Pine Needles | E23: Cal-L.STD | F23: ='ISIRF RAW'!B36 -> 37 | G23: ='ISIRF RAW'!C36 -> 6.574 | H23: ='ISIRF RAW'!F36 -> 34.086204 | I23: ='ISIRF RAW'!G36 -> 485313664 | J23: ='ISIRF RAW'!M36 -> 51.494598 | K23: ='ISIRF RAW'!O36 -> -25.888578
A24: ='ISIRF RAW'!S61 -> 45741.12 | B24: ='ISIRF RAW'!T61 -> IC15N-241218-10KansasRoarCarbon-3_56.raw | D24: ='ISIRF RAW'!A61 -> NBS 1575 Pine Needles | E24: Cal-L.STD | F24: ='ISIRF RAW'!B61 -> 62 | G24: ='ISIRF RAW'!C61 -> 6.873 | H24: ='ISIRF RAW'!F61 -> 34.45842 | I24: ='ISIRF RAW'!G61 -> 507203456 | J24: ='ISIRF RAW'!M61 -> 51.62033 | K24: ='ISIRF RAW'!O61 -> -25.966105
A26: QA Summary 13C: | B26: 13C | E26: %C | H26: N
B27: Avg | C27: Variance | D27: s.d. | E27: X | F27: Variance | G27: r.s.d
A28: REP1 (‰) | B28: =AVERAGE('ISIRF RAW'!O12,'ISIRF RAW'!O56) -> -17.516797 | C28: =VAR('ISIRF RAW'!O12,'ISIRF RAW'!O56) -> 0.016548727 | D28: =STDEV('ISIRF RAW'!O12,'ISIRF RAW'!O56) -> 0.12864185 | E28: =AVERAGE('ISIRF RAW'!M12,'ISIRF RAW'!M56) -> 1.447397 | F28: =VAR('ISIRF RAW'!M12,'ISIRF RAW'!M56) -> 0.0085218657 | G28: =(STDEV('ISIRF RAW'!M12,'ISIRF RAW'!M56))/E28 -> 0.06377929 | H28: =COUNT('ISIRF RAW'!M12,'ISIRF RAW'!M56) -> 2
A29: REP2 (‰) | B29: =AVERAGE('ISIRF RAW'!O26:O27) -> -16.917573 | C29: =VAR('ISIRF RAW'!O26:O27) -> 0.0069901302 | D29: =STDEV('ISIRF RAW'!O26:O27) -> 0.083606999 | E29: =AVERAGE('ISIRF RAW'!M26:M27) -> 2.6758166 | F29: =VAR('ISIRF RAW'!M26:M27) -> 0.040167672 | G29: =(STDEV('ISIRF RAW'!M26:M27))/E29 -> 0.074900029 | H29: =COUNT('ISIRF RAW'!M26:M27) -> 2
A30: =B4 -> QC.STD | B30: =AVERAGE(K11:K15) -> -12.889084 | C30: =VAR(K11:K15) -> 0.024479141 | D30: =STDEV(K11:K15) -> 0.15645811 | E30: =AVERAGE(J11:J15) -> 33.509499 | F30: =VAR(J11:J15) -> 0.8278945 | G30: =(STDEV(J11:J15))/E30 -> 0.027153109 | H30: =COUNT(J11:J15) -> 5
A31: =B5 -> Cal-H.STD | B31: =AVERAGE(K16:K18) -> -21.211343 | C31: =VAR(K16:K18) -> 0.015800556 | D31: =STDEV(K16:K18) -> 0.12570026 | E31: =AVERAGE(J16:J18) -> 46.049389 | F31: =VAR(J16:J18) -> 0.4334643 | G31: =(STDEV(J16:J18))/E31 -> 0.014297259 | H31: =COUNT(J16:J18) -> 3
A32: =B6 -> Cal-L.STD | B32: =AVERAGE(K19:K21) -> -30.283739 | C32: =VAR(K19:K21) -> 0.013382332 | D32: =STDEV(K19:K21) -> 0.11568203 | E32: =AVERAGE(J19:J21) -> 44.365154 | F32: =VAR(J19:J21) -> 0.90607348 | G32: =(STDEV(J19:J21))/E32 -> 0.021455553 | H32: =COUNT(J19:J21) -> 3
A33: =B7 -> Check QC | B33: =AVERAGE(K22:K24) -> -25.890863 | C33: =VAR(K22:K24) -> 0.0054946423 | D33: =STDEV(K22:K24) -> 0.074125854 | E33: =AVERAGE(J22:J24) -> 51.553406 | F33: =VAR(J22:J24) -> 0.0040015174 | G33: =(STDEV(J22:J24))/E33 -> 0.0012270295 | H33: =COUNT(J22:J24) -> 3
B35: Notes:

Sheet Tables
A1: NBS/NIST | B1: Standard | C1: Targ. Wt | E1: Last Name | F1: First Name | G1: Branch | H1: ID Number | I1: Address | J1: email Address | K1: Phone
A2: B2157 Wheat Flour | B2: Wheat Flour | C2: 3 | E2: Anderson | F2: Chris | G2: EEB | H2: 11 | I2: Corvallis Anx A16 | J2: andersen.Christian@epa.gov | K2: 4791
A3: B2159 Sorghum Flour | B3: Sorghum Flour | C3: 3 | E3: Brooks | F3: Reneé | G3: EEB | H3: 8 | I3: Corvallis Bldg 74 | J3: brooks.reneej@epa.gov | K3: 4684
A4: ISIRF Bamboo | B4: Bamboo | C4: 1.5 | E4: Compton | F4: Jana | G4: FEB | H4: 10 | I4: Corvallis MOD 130 | J4: compton.jana@epa.gov | K4: 4620
A5: NBS 1577 Bovine Liver | B5: Bovine Liver | C5: 1 | E5: Dewitt | F5: Ted | G5: PCEB | H5: 19 | I5: Newport A-102 | J5: dewitt.ted@epa.gov | K5: 4029
A6: ISIRF Chitin | B6: Chitin | C6: 1 | E6: Faulkner | F6: Bart | G6: Ada | H6: 23
A7: NBS 1572 Citrus Leaf | B7: Citrus Leaf | C7: 2 | E7: Forshey | F7: Ken | G7: Ada | H7: 22
A8: NBS 8412 Corn Stalk | B8: Corn Stalk | C8: 6.5 | E8: Johnson | F8: Mark | G8: EEB | H8: 2 | I8: Corvallis PEB 112 | J8: johnson.markg@epa.gov | K8: 4696
A9: NBS 1575 Pine Needles | B9: Pine Needles | C9: 6.5 | E9: Kaldy | F9: Jim | G9: CEB | H9: 16 | I9: Newport A-124 | J9: kaldy.james@epa.gov | K9: 4026
A10: NIST 8541 Graphite | B10: Graphite | C10: 0.5 | E10: Lee | F10: Henry | G10: EEB | H10: 17 | I10: Corvallis PEB 117 | K10: 4832
A11: NIST 8542 Sucrose | B11: Sucrose | C11: 1 | E11: McKane | F11: Bob | G11: EEB | H11: 14 | I11: Corvallis SSB 202 | K11: 4631
A12: NIST 8550 Am Sulf | B12: Ammonium Sulfate | C12: 0.5 | E12: Nahlik | F12: Amanda | G12: FEB | H12: 24 | I12: Corvallis Main-208 | J12: nahlik.amanda@epa.gov | K12: 4581
A13: NIST 8551 Am Sulf | B13: Ammonium Sulfate | C13: 0.5 | E13: Olszyk | F13: Dave | G13: EEB | H13: 13 | I13: Corvallis SSB 206 | K13: 4397
A14: NIST 8573 Glutamic | B14: L-Glutamic | C14: 0.5 | E14: Rugh | F14: QA QC | G14: ISIRF | H14: 0 | I14: Corvallis Main-201 | J14: rugh.william@epa.gov | K14: 4604
