Workbook
Name Standards: Tables!$A$2:$A$17

Sheet COVER
B2: FILE NAME: | C2: ="IC"&C15&"-"&C23&"-"&C22&C8 -> IC15N-240610-10KansasROAR-4
B4: ISIRF Isotope Cube INLET SUBMISSION FORM -- AS OF 4/29/2024
B6: PESD Project: | C6: Kansas ROAR Project
B7: Project Description: | C7: The Kansas ROAR projects investigates soil health practices influences over nitrate leaching (Soil Samples collected from 0-8 inches in Kansas farmlands)
B8: Project Code & Tray ID for file name: | C8: KansasROAR-4
B9: Investigator: | C9: Compton
B10: Affiliation: | C10: =VLOOKUP($C$9,Table1[],3) -> FEB
B11: Address: | C11: =VLOOKUP($C$9,Table1[],5) -> Corvallis MOD 130
B12: Email: | C12: =VLOOKUP($C$9,Table1[],6) -> compton.jana@epa.gov
B13: Phone: | C13: =VLOOKUP($C$9,Table1[],7) -> 4620
B14: Weigh Person: | C14: Janice Chatfield
B15: Analyses (13C, 15N, 34S): | C15: 15N
B16: Sample %C
B17: Sample %N
B18: Sample %S
B19: Sample Description (Matrix): | C19: Soil
B20: Enriched Samples? (Y or N): | C20: No
B21: HazardousSamples? (Y or N): | C21: No
B22: Investigator ID# | C22: =VLOOKUP($C$9,Table1[],4) -> 10
B23: Date: (YYMMDD) | C23: 240610
B26: DIRECTIONS:
B27: 1. Obtain the ISIRF Solid Submission Form from the mass spectrometer operator.
B28: 2. Fill in the yellow shaded regions of the Cover, and Investigator Data Sheets (34 samples maximum).
B29: 3. Rename this file with the File name in dark tan box above, and e-mail to Lisandra Trine
B30: 4. ISIRF will identify standards and sample weights needed, and print the weighsheet.
B31: 5. ISIRF will give your weigh sheet to the trained weigh person identified above.
B32: 6. Have Weigh person submit samples and Weigh Sheet to the IRMS operator.
B34: INDEX
B35: Tab | C35: Contents
B36: Cover | C36: PI Project and sample discription
B37: Investigator Data | C37: PI Sample identification, and Results
B38: Weigh Sheet | C38: Printable Sheet for hand entering weights
B39: Investigator QA Data | C39: PI and ISIRF Quality Assurance Information
B40: ISIRF Raw | C40: ISIRF use for raw data entery
B41: ISIRF 15N | C41: ISIRF use for d15N summary
B42: ISIRF 13C | C42: ISIRF use for d13C summary
B43: ISIRF 34S | C43: ISIRF use for d34S summary
B44: Tables | C44: ISIRF use for updated tables
B45: Revisions | C45: ISIRF revision summary

Sheet Investigator Data
B2: FILE NAME: | C2: =COVER!C2 -> IC15N-240610-10KansasROAR-4 | I2: User Data
A3: Sample # | B3: Sample ID | C3: Target Wt. | D3: %C | E3: δ13C | F3: %N | G3: δ15N | H3: C/N
A4: Rep 1 | B4: 20240407_S2_J | C4: 30 | D4: =IF(COUNT('ISIRF RAW'!M12,'ISIRF RAW'!M56)=0,"",AVERAGE('ISIRF RAW'!M12,'ISIRF RAW'!M56)) | E4: =IF(COUNT('ISIRF RAW'!O12,'ISIRF RAW'!O56)=0,"",AVERAGE('ISIRF RAW'!O12,'ISIRF RAW'!O56)) | F4: =IF(COUNT('ISIRF RAW'!J12,'ISIRF RAW'!J56)=0,"",AVERAGE('ISIRF RAW'!J12,'ISIRF RAW'!J56)) | G4: =IF(COUNT('ISIRF RAW'!L12,'ISIRF RAW'!L56)=0,"", AVERAGE('ISIRF RAW'!L12,'ISIRF RAW'!L56)) | H4: =D4/F4 -> #VALUE!
A5: 2 | B5: 20240407_S3_A | C5: 30 | D5: =IF(COUNT('ISIRF RAW'!M13)=0,"",'ISIRF RAW'!M13) | E5: =IF(COUNT('ISIRF RAW'!O13)=0,"",'ISIRF RAW'!O13) | F5: =IF(COUNT('ISIRF RAW'!J13)=0,"",'ISIRF RAW'!J13) | G5: =IF(COUNT('ISIRF RAW'!L13)=0,"",'ISIRF RAW'!L13) | H5: =D5/F5 -> #VALUE!
A6: 3 | B6: 20240407_S3_B | C6: 30 | D6: =IF(COUNT('ISIRF RAW'!M14)=0,"",'ISIRF RAW'!M14) | E6: =IF(COUNT('ISIRF RAW'!O14)=0,"",'ISIRF RAW'!O14) | F6: =IF(COUNT('ISIRF RAW'!J14)=0,"",'ISIRF RAW'!J14) | G6: =IF(COUNT('ISIRF RAW'!L14)=0,"",'ISIRF RAW'!L14) | H6: =D6/F6 -> #VALUE!
A7: 4 | B7: 20240407_S3_C | C7: 30 | D7: =IF(COUNT('ISIRF RAW'!M15)=0,"",'ISIRF RAW'!M15) | E7: =IF(COUNT('ISIRF RAW'!O15)=0,"",'ISIRF RAW'!O15) | F7: =IF(COUNT('ISIRF RAW'!J15)=0,"",'ISIRF RAW'!J15) | G7: =IF(COUNT('ISIRF RAW'!L15)=0,"",'ISIRF RAW'!L15) | H7: =D7/F7 -> #VALUE!
A8: 5 | B8: 20240407_S3_D | C8: 30 | D8: =IF(COUNT('ISIRF RAW'!M16)=0,"",'ISIRF RAW'!M16) | E8: =IF(COUNT('ISIRF RAW'!O16)=0,"",'ISIRF RAW'!O16) | F8: =IF(COUNT('ISIRF RAW'!J16)=0,"",'ISIRF RAW'!J16) | G8: =IF(COUNT('ISIRF RAW'!L16)=0,"",'ISIRF RAW'!L16) | H8: =D8/F8 -> #VALUE!
A9: 6 | B9: 20240407_S3_E | C9: 30 | D9: =IF(COUNT('ISIRF RAW'!M17)=0,"",'ISIRF RAW'!M17) | E9: =IF(COUNT('ISIRF RAW'!O17)=0,"",'ISIRF RAW'!O17) | F9: =IF(COUNT('ISIRF RAW'!J17)=0,"",'ISIRF RAW'!J17) | G9: =IF(COUNT('ISIRF RAW'!L17)=0,"",'ISIRF RAW'!L17) | H9: =D9/F9 -> #VALUE!
A10: 7 | B10: 20240407_S3_F | C10: 30 | D10: =IF(COUNT('ISIRF RAW'!M18)=0,"",'ISIRF RAW'!M18) | E10: =IF(COUNT('ISIRF RAW'!O18)=0,"",'ISIRF RAW'!O18) | F10: =IF(COUNT('ISIRF RAW'!J18)=0,"",'ISIRF RAW'!J18) | G10: =IF(COUNT('ISIRF RAW'!L18)=0,"",'ISIRF RAW'!L18) | H10: =D10/F10 -> #VALUE!
A11: 8 | B11: 20240407_S4_A | C11: 30 | D11: =IF(COUNT('ISIRF RAW'!M19)=0,"",'ISIRF RAW'!M19) | E11: =IF(COUNT('ISIRF RAW'!O19)=0,"",'ISIRF RAW'!O19) | F11: =IF(COUNT('ISIRF RAW'!J19)=0,"",'ISIRF RAW'!J19) | G11: =IF(COUNT('ISIRF RAW'!L19)=0,"",'ISIRF RAW'!L19) | H11: =D11/F11 -> #VALUE!
A12: 9 | B12: 20240407_S4_A _Dup | C12: 30 | D12: =IF(COUNT('ISIRF RAW'!M20)=0,"",'ISIRF RAW'!M20) | E12: =IF(COUNT('ISIRF RAW'!O20)=0,"",'ISIRF RAW'!O20) | F12: =IF(COUNT('ISIRF RAW'!J20)=0,"",'ISIRF RAW'!J20) | G12: =IF(COUNT('ISIRF RAW'!L20)=0,"",'ISIRF RAW'!L20) | H12: =D12/F12 -> #VALUE!
A13: 10 | B13: 20240407_S4_B | C13: 30 | D13: =IF(COUNT('ISIRF RAW'!M22)=0,"",'ISIRF RAW'!M22) | E13: =IF(COUNT('ISIRF RAW'!O22)=0,"",'ISIRF RAW'!O22) | F13: =IF(COUNT('ISIRF RAW'!J22)=0,"",'ISIRF RAW'!J22) | G13: =IF(COUNT('ISIRF RAW'!L22)=0,"",'ISIRF RAW'!L22) | H13: =D13/F13 -> #VALUE!
A14: 11 | B14: 20240407_S4_C | C14: 30 | D14: =IF(COUNT('ISIRF RAW'!M23)=0,"",'ISIRF RAW'!M23) | E14: =IF(COUNT('ISIRF RAW'!O23)=0,"",'ISIRF RAW'!O23) | F14: =IF(COUNT('ISIRF RAW'!J23)=0,"",'ISIRF RAW'!J23) | G14: =IF(COUNT('ISIRF RAW'!L23)=0,"",'ISIRF RAW'!L23) | H14: =D14/F14 -> #VALUE!
A15: 12 | B15: 20240407_S4_D | C15: 30 | D15: =IF(COUNT('ISIRF RAW'!M24)=0,"",'ISIRF RAW'!M24) | E15: =IF(COUNT('ISIRF RAW'!O24)=0,"",'ISIRF RAW'!O24) | F15: =IF(COUNT('ISIRF RAW'!J24)=0,"",'ISIRF RAW'!J24) | G15: =IF(COUNT('ISIRF RAW'!L24)=0,"",'ISIRF RAW'!L24) | H15: =D15/F15 -> #VALUE!
A16: 13 | B16: 20240407_S4_E | C16: 30 | D16: =IF(COUNT('ISIRF RAW'!M25)=0,"",'ISIRF RAW'!M25) | E16: =IF(COUNT('ISIRF RAW'!O25)=0,"",'ISIRF RAW'!O25) | F16: =IF(COUNT('ISIRF RAW'!J25)=0,"",'ISIRF RAW'!J25) | G16: =IF(COUNT('ISIRF RAW'!L25)=0,"",'ISIRF RAW'!L25) | H16: =D16/F16 -> #VALUE!
A17: Rep 14 | B17: 20240407_S4_F | C17: 30 | D17: =IF(COUNT('ISIRF RAW'!M26,'ISIRF RAW'!M27)=0,"",AVERAGE('ISIRF RAW'!M26,'ISIRF RAW'!M27)) | E17: =IF(COUNT('ISIRF RAW'!O26,'ISIRF RAW'!O27)=0,"",AVERAGE('ISIRF RAW'!O26,'ISIRF RAW'!O27)) | F17: =IF(COUNT('ISIRF RAW'!J26,'ISIRF RAW'!J27)=0,"",AVERAGE('ISIRF RAW'!J26,'ISIRF RAW'!J27)) | G17: =IF(COUNT('ISIRF RAW'!L26,'ISIRF RAW'!L27)=0,"", AVERAGE('ISIRF RAW'!L26,'ISIRF RAW'!L27)) | H17: =D17/F17 -> #VALUE!
A18: 15 | B18: 20240407_S4_G | C18: 30 | D18: =IF(COUNT('ISIRF RAW'!M28)=0,"",'ISIRF RAW'!M28) | E18: =IF(COUNT('ISIRF RAW'!O28)=0,"",'ISIRF RAW'!O28) | F18: =IF(COUNT('ISIRF RAW'!J28)=0,"",'ISIRF RAW'!J28) | G18: =IF(COUNT('ISIRF RAW'!L28)=0,"",'ISIRF RAW'!L28) | H18: =D18/F18 -> #VALUE!
A19: 16 | B19: 20240407_S4_H | C19: 30 | D19: =IF(COUNT('ISIRF RAW'!M29)=0,"",'ISIRF RAW'!M29) | E19: =IF(COUNT('ISIRF RAW'!O29)=0,"",'ISIRF RAW'!O29) | F19: =IF(COUNT('ISIRF RAW'!J29)=0,"",'ISIRF RAW'!J29) | G19: =IF(COUNT('ISIRF RAW'!L29)=0,"",'ISIRF RAW'!L29) | H19: =D19/F19 -> #VALUE!
A20: 17 | B20: 20240407_S4_I | C20: 30 | D20: =IF(COUNT('ISIRF RAW'!M30)=0,"",'ISIRF RAW'!M30) | E20: =IF(COUNT('ISIRF RAW'!O30)=0,"",'ISIRF RAW'!O30) | F20: =IF(COUNT('ISIRF RAW'!J30)=0,"",'ISIRF RAW'!J30) | G20: =IF(COUNT('ISIRF RAW'!L30)=0,"",'ISIRF RAW'!L30) | H20: =D20/F20 -> #VALUE!
A21: 18 | B21: 20240407_S4_J | C21: 30 | D21: =IF(COUNT('ISIRF RAW'!M31)=0,"",'ISIRF RAW'!M31) | E21: =IF(COUNT('ISIRF RAW'!O31)=0,"",'ISIRF RAW'!O31) | F21: =IF(COUNT('ISIRF RAW'!J31)=0,"",'ISIRF RAW'!J31) | G21: =IF(COUNT('ISIRF RAW'!L31)=0,"",'ISIRF RAW'!L31) | H21: =D21/F21 -> #VALUE!
A22: 19 | B22: 20240407_SS1_A | C22: 30 | D22: =IF(COUNT('ISIRF RAW'!M37)=0,"",'ISIRF RAW'!M37) | E22: =IF(COUNT('ISIRF RAW'!O37)=0,"",'ISIRF RAW'!O37) | F22: =IF(COUNT('ISIRF RAW'!J37)=0,"",'ISIRF RAW'!J37) | G22: =IF(COUNT('ISIRF RAW'!L37)=0,"",'ISIRF RAW'!L37) | H22: =D22/F22 -> #VALUE!
A23: 20 | B23: 20240407_SS1_B | C23: 30 | D23: =IF(COUNT('ISIRF RAW'!M38)=0,"",'ISIRF RAW'!M38) | E23: =IF(COUNT('ISIRF RAW'!O38)=0,"",'ISIRF RAW'!O38) | F23: =IF(COUNT('ISIRF RAW'!J38)=0,"",'ISIRF RAW'!J38) | G23: =IF(COUNT('ISIRF RAW'!L38)=0,"",'ISIRF RAW'!L38) | H23: =D23/F23 -> #VALUE!
A24: 21 | B24: 20240407_SS1_C | C24: 30 | D24: =IF(COUNT('ISIRF RAW'!M39)=0,"",'ISIRF RAW'!M39) | E24: =IF(COUNT('ISIRF RAW'!O39)=0,"",'ISIRF RAW'!O39) | F24: =IF(COUNT('ISIRF RAW'!J39)=0,"",'ISIRF RAW'!J39) | G24: =IF(COUNT('ISIRF RAW'!L39)=0,"",'ISIRF RAW'!L39) | H24: =D24/F24 -> #VALUE!
A25: 22 | B25: 20240407_SS1_D | C25: 30 | D25: =IF(COUNT('ISIRF RAW'!M40)=0,"",'ISIRF RAW'!M40) | E25: =IF(COUNT('ISIRF RAW'!O40)=0,"",'ISIRF RAW'!O40) | F25: =IF(COUNT('ISIRF RAW'!J40)=0,"",'ISIRF RAW'!J40) | G25: =IF(COUNT('ISIRF RAW'!L40)=0,"",'ISIRF RAW'!L40) | H25: =D25/F25 -> #VALUE!
A26: 23 | B26: 20240407_SS1_E | C26: 30 | D26: =IF(COUNT('ISIRF RAW'!M41)=0,"",'ISIRF RAW'!M41) | E26: =IF(COUNT('ISIRF RAW'!O41)=0,"",'ISIRF RAW'!O41) | F26: =IF(COUNT('ISIRF RAW'!J41)=0,"",'ISIRF RAW'!J41) | G26: =IF(COUNT('ISIRF RAW'!L41)=0,"",'ISIRF RAW'!L41) | H26: =D26/F26 -> #VALUE!
A27: 24 | B27: 20240407_SS1_F | C27: 30 | D27: =IF(COUNT('ISIRF RAW'!M42)=0,"",'ISIRF RAW'!M42) | E27: =IF(COUNT('ISIRF RAW'!O42)=0,"",'ISIRF RAW'!O42) | F27: =IF(COUNT('ISIRF RAW'!J42)=0,"",'ISIRF RAW'!J42) | G27: =IF(COUNT('ISIRF RAW'!L42)=0,"",'ISIRF RAW'!L42) | H27: =D27/F27 -> #VALUE!
A28: 25 | B28: 20240407_SS1_G | C28: 30 | D28: =IF(COUNT('ISIRF RAW'!M43)=0,"",'ISIRF RAW'!M43) | E28: =IF(COUNT('ISIRF RAW'!O43)=0,"",'ISIRF RAW'!O43) | F28: =IF(COUNT('ISIRF RAW'!J43)=0,"",'ISIRF RAW'!J43) | G28: =IF(COUNT('ISIRF RAW'!L43)=0,"",'ISIRF RAW'!L43) | H28: =D28/F28 -> #VALUE!
A29: 26 | B29: 20240407_SS1_H | C29: 30 | D29: =IF(COUNT('ISIRF RAW'!M44)=0,"",'ISIRF RAW'!M44) | E29: =IF(COUNT('ISIRF RAW'!O44)=0,"",'ISIRF RAW'!O44) | F29: =IF(COUNT('ISIRF RAW'!J44)=0,"",'ISIRF RAW'!J44) | G29: =IF(COUNT('ISIRF RAW'!L44)=0,"",'ISIRF RAW'!L44) | H29: =D29/F29 -> #VALUE!
A30: 27 | B30: 20240407_SS1_I | C30: 30 | D30: =IF(COUNT('ISIRF RAW'!M45)=0,"",'ISIRF RAW'!M45) | E30: =IF(COUNT('ISIRF RAW'!O45)=0,"",'ISIRF RAW'!O45) | F30: =IF(COUNT('ISIRF RAW'!J45)=0,"",'ISIRF RAW'!J45) | G30: =IF(COUNT('ISIRF RAW'!L45)=0,"",'ISIRF RAW'!L45) | H30: =D30/F30 -> #VALUE!
A31: 28 | B31: 20240407_SS1_J | C31: 30 | D31: =IF(COUNT('ISIRF RAW'!M47)=0,"",'ISIRF RAW'!M47) | E31: =IF(COUNT('ISIRF RAW'!O47)=0,"",'ISIRF RAW'!O47) | F31: =IF(COUNT('ISIRF RAW'!J47)=0,"",'ISIRF RAW'!J47) | G31: =IF(COUNT('ISIRF RAW'!L47)=0,"",'ISIRF RAW'!L47) | H31: =D31/F31 -> #VALUE!
A32: 29 | B32: 20240407_SS1_K | C32: 30 | D32: =IF(COUNT('ISIRF RAW'!M48)=0,"",'ISIRF RAW'!M48) | E32: =IF(COUNT('ISIRF RAW'!O48)=0,"",'ISIRF RAW'!O48) | F32: =IF(COUNT('ISIRF RAW'!J48)=0,"",'ISIRF RAW'!J48) | G32: =IF(COUNT('ISIRF RAW'!L48)=0,"",'ISIRF RAW'!L48) | H32: =D32/F32 -> #VALUE!
A33: 30 | B33: 20240407_W1_A | C33: 30 | D33: =IF(COUNT('ISIRF RAW'!M49)=0,"",'ISIRF RAW'!M49) | E33: =IF(COUNT('ISIRF RAW'!O49)=0,"",'ISIRF RAW'!O49) | F33: =IF(COUNT('ISIRF RAW'!J49)=0,"",'ISIRF RAW'!J49) | G33: =IF(COUNT('ISIRF RAW'!L49)=0,"",'ISIRF RAW'!L49) | H33: =D33/F33 -> #VALUE!
A34: 31 | B34: 20240407_W1_B | C34: 30 | D34: =IF(COUNT('ISIRF RAW'!M50)=0,"",'ISIRF RAW'!M50) | E34: =IF(COUNT('ISIRF RAW'!O50)=0,"",'ISIRF RAW'!O50) | F34: =IF(COUNT('ISIRF RAW'!J50)=0,"",'ISIRF RAW'!J50) | G34: =IF(COUNT('ISIRF RAW'!L50)=0,"",'ISIRF RAW'!L50) | H34: =D34/F34 -> #VALUE!
A35: 32 | B35: 20240407_W1_C | C35: 30 | D35: =IF(COUNT('ISIRF RAW'!M51)=0,"",'ISIRF RAW'!M51) | E35: =IF(COUNT('ISIRF RAW'!O51)=0,"",'ISIRF RAW'!O51) | F35: =IF(COUNT('ISIRF RAW'!J51)=0,"",'ISIRF RAW'!J51) | G35: =IF(COUNT('ISIRF RAW'!L51)=0,"",'ISIRF RAW'!L51) | H35: =D35/F35 -> #VALUE!
A36: 33 | B36: 20240407_W1_D | C36: 30 | D36: =IF(COUNT('ISIRF RAW'!M52)=0,"",'ISIRF RAW'!M52) | E36: =IF(COUNT('ISIRF RAW'!O52)=0,"",'ISIRF RAW'!O52) | F36: =IF(COUNT('ISIRF RAW'!J52)=0,"",'ISIRF RAW'!J52) | G36: =IF(COUNT('ISIRF RAW'!L52)=0,"",'ISIRF RAW'!L52) | H36: =D36/F36 -> #VALUE!
A37: 34 | B37: 20240407_W1_E | C37: 30 | D37: =IF(COUNT('ISIRF RAW'!M53)=0,"",'ISIRF RAW'!M53) | E37: =IF(COUNT('ISIRF RAW'!O53)=0,"",'ISIRF RAW'!O53) | F37: =IF(COUNT('ISIRF RAW'!J53)=0,"",'ISIRF RAW'!J53) | G37: =IF(COUNT('ISIRF RAW'!L53)=0,"",'ISIRF RAW'!L53) | H37: =D37/F37 -> #VALUE!
A38: 35 | B38: 20240407_W1_F | C38: 30 | D38: =IF(COUNT('ISIRF RAW'!M54)=0,"",'ISIRF RAW'!M54) | E38: =IF(COUNT('ISIRF RAW'!O54)=0,"",'ISIRF RAW'!O54) | F38: =IF(COUNT('ISIRF RAW'!J54)=0,"",'ISIRF RAW'!J54) | G38: =IF(COUNT('ISIRF RAW'!L54)=0,"",'ISIRF RAW'!L54) | H38: =D38/F38 -> #VALUE!
A39: 36 | B39: 20240407_W1_F_Dup | C39: 30 | D39: =IF(COUNT('ISIRF RAW'!M55)=0,"",'ISIRF RAW'!M55) | E39: =IF(COUNT('ISIRF RAW'!O55)=0,"",'ISIRF RAW'!O55) | F39: =IF(COUNT('ISIRF RAW'!J55)=0,"",'ISIRF RAW'!J55) | G39: =IF(COUNT('ISIRF RAW'!L55)=0,"",'ISIRF RAW'!L55) | H39: =D39/F39 -> #VALUE!

Sheet Weigh Sheet
A1: =COVER!B4 -> ISIRF Isotope Cube INLET SUBMISSION FORM -- AS OF 4/29/2024 | F1: #Samples | G1: =COUNTA('Investigator Data'!B4:B39) -> 36
B2: FILE NAME: | C2: =COVER!C2 -> IC15N-240610-10KansasROAR-4 | E2: WRITE FULL FILE NAME ON TRAY!!
A3: WEIGH INFO: | D3: Wt. (mg) | E3: Calibration Info. Balance:
A4: Sample Description: | C4: =COVER!C19 -> Soil | E4: Date | F4: Balance Log Book
A5: Sample %N, %C: | C5: =COVER!C16 -> 0
A6: Analyses: | C6: =COVER!C15 -> 15N
A7: Weigh Person: | C7: =COVER!C14 -> Janice Chatfield
A8: Sample Weight:
A9: QC.Std: | C9: ISIRF Ulva | D9: =VLOOKUP(C9,Tables!A2:C17,3,FALSE) -> 1.2
A10: Cal-H.Std: | C10: ISIRF Chitin | D10: =VLOOKUP(C10,Tables!A2:C17,3,FALSE) -> 1 | E10: ISIRF USE ONLY
A11: Cal-L.Std: | C11: ISIRF Bamboo | D11: =VLOOKUP(C11,Tables!A2:C17,3,FALSE) -> 1.5 | E11: DATE SUBMITTED: | G11: =IF(COUNTA(COVER!C23)=0,"",COVER!C23) -> 240610
A12: QA Std: | C12: NBS 1572 Citrus Leaf | D12: =VLOOKUP(C12,Tables!A2:C17,3,FALSE) -> 2 | E12: DATE RUN: | G12: =IF(COUNTA('ISIRF RAW'!B2)=0,"",'ISIRF RAW'!B2)
A13: Sample Cup | C13: Tin | D13: 5 X 9 | E13: ANALYST: | G13: =IF(COUNTA('ISIRF RAW'!B3)=0,"",'ISIRF RAW'!B3)
A14: CO2 Dilution: @ 40 psi | D14: 5 | E14: Mode of Operation | G14: =COVER!C15 -> 15N
A16: ISIRF# | B16: Well# | C16: Sample ID | D16: Target Wt. | E16: Sample Wt. | F16: Seq.
A17: ="IC"&COVER!C$15&COVER!C$23&"-"&COVER!C$22&F17 -> IC15N240610-101 | B17: A1 | C17: blank | E17: - | F17: 1
A18: ="IC"&COVER!C$15&COVER!C$23&"-"&COVER!C$22&F18 -> IC15N240610-102 | B18: A2 | C18: blank | E18: - | F18: =F17+1 -> 2
A19: ="IC"&COVER!C$15&COVER!C$23&"-"&COVER!C$22&F19 -> IC15N240610-103 | B19: A3 | C19: =$C$9 -> ISIRF Ulva | D19: =$D$9 -> 1.2 | E19: 1.273 | F19: =F18+1 -> 3
A20: ="IC"&COVER!C$15&COVER!C$23&"-"&COVER!C$22&F20 -> IC15N240610-104 | B20: A4 | C20: =$C$10 -> ISIRF Chitin | D20: =$D$10 -> 1 | E20: 1.038 | F20: =F19+1 -> 4
A21: ="IC"&COVER!C$15&COVER!C$23&"-"&COVER!C$22&F21 -> IC15N240610-105 | B21: A5 | C21: =$C$11 -> ISIRF Bamboo | D21: =$D$11 -> 1.5 | E21: 1.496 | F21: =F20+1 -> 5
A22: ="IC"&COVER!C$15&COVER!C$23&"-"&COVER!C$22&F22 -> IC15N240610-106 | B22: A6 | C22: =C12 -> NBS 1572 Citrus Leaf | D22: =D12 -> 2 | E22: 2.038 | F22: =F21+1 -> 6
A23: ="IC"&COVER!C$15&COVER!C$23&"-"&COVER!C$22&F23 -> IC15N240610-107 | B23: A7 | C23: =IF('Investigator Data'!B4="","","R1-"&'Investigator Data'!B4) -> R1-20240407_S2_J | D23: =IF('Investigator Data'!C4="",$D$8,'Investigator Data'!C4) -> 30 | E23: 29.098 | F23: =F22+1 -> 7
A24: ="IC"&COVER!C$15&COVER!C$23&"-"&COVER!C$22&F24 -> IC15N240610-108 | B24: A8 | C24: =IF('Investigator Data'!B5="","",'Investigator Data'!B5) -> 20240407_S3_A | D24: =IF('Investigator Data'!C5="",$D$8,'Investigator Data'!C5) -> 30 | E24: 29.412 | F24: =F23+1 -> 8
A25: ="IC"&COVER!C$15&COVER!C$23&"-"&COVER!C$22&F25 -> IC15N240610-109 | B25: A9 | C25: =IF('Investigator Data'!B6="","",'Investigator Data'!B6) -> 20240407_S3_B | D25: =IF('Investigator Data'!C6="",$D$8,'Investigator Data'!C6) -> 30 | E25: 29.901 | F25: =F24+1 -> 9
A26: ="IC"&COVER!C$15&COVER!C$23&"-"&COVER!C$22&F26 -> IC15N240610-1010 | B26: A10 | C26: =IF('Investigator Data'!B7="","",'Investigator Data'!B7) -> 20240407_S3_C | D26: =IF('Investigator Data'!C7="",$D$8,'Investigator Data'!C7) -> 30 | E26: 30.36 | F26: =F25+1 -> 10
A27: ="IC"&COVER!C$15&COVER!C$23&"-"&COVER!C$22&F27 -> IC15N240610-1011 | B27: A11 | C27: =IF('Investigator Data'!B8="","",'Investigator Data'!B8) -> 20240407_S3_D | D27: =IF('Investigator Data'!C8="",$D$8,'Investigator Data'!C8) -> 30 | E27: 30.61 | F27: =F26+1 -> 11
A28: ="IC"&COVER!C$15&COVER!C$23&"-"&COVER!C$22&F28 -> IC15N240610-1012 | B28: A12 | C28: =IF('Investigator Data'!B9="","",'Investigator Data'!B9) -> 20240407_S3_E | D28: =IF('Investigator Data'!C9="",$D$8,'Investigator Data'!C9) -> 30 | E28: 30.025 | F28: =F27+1 -> 12
A29: ="IC"&COVER!C$15&COVER!C$23&"-"&COVER!C$22&F29 -> IC15N240610-1013 | B29: B1 | C29: =IF('Investigator Data'!B10="","",'Investigator Data'!B10) -> 20240407_S3_F | D29: =IF('Investigator Data'!C10="",$D$8,'Investigator Data'!C10) -> 30 | E29: 30.36 | F29: =F28+1 -> 13
A30: ="IC"&COVER!C$15&COVER!C$23&"-"&COVER!C$22&F30 -> IC15N240610-1014 | B30: B2 | C30: =IF('Investigator Data'!B11="","",'Investigator Data'!B11) -> 20240407_S4_A | D30: =IF('Investigator Data'!C11="",$D$8,'Investigator Data'!C11) -> 30 | E30: 29.55 | F30: =F29+1 -> 14
A31: ="IC"&COVER!C$15&COVER!C$23&"-"&COVER!C$22&F31 -> IC15N240610-1015 | B31: B3 | C31: =IF('Investigator Data'!B12="","",'Investigator Data'!B12) -> 20240407_S4_A _Dup | D31: =IF('Investigator Data'!C12="",$D$8,'Investigator Data'!C12) -> 30 | E31: 29.598 | F31: =F30+1 -> 15
A32: ="IC"&COVER!C$15&COVER!C$23&"-"&COVER!C$22&F32 -> IC15N240610-1016 | B32: B4 | C32: =$C$9 -> ISIRF Ulva | D32: =$D$9 -> 1.2 | E32: 1.261 | F32: =F31+1 -> 16
A33: ="IC"&COVER!C$15&COVER!C$23&"-"&COVER!C$22&F33 -> IC15N240610-1017 | B33: B5 | C33: =IF('Investigator Data'!B13="","",'Investigator Data'!B13) -> 20240407_S4_B | D33: =IF('Investigator Data'!C13="",$D$8,'Investigator Data'!C13) -> 30 | E33: 30.278 | F33: =F32+1 -> 17
A34: ="IC"&COVER!C$15&COVER!C$23&"-"&COVER!C$22&F34 -> IC15N240610-1018 | B34: B6 | C34: =IF('Investigator Data'!B14="","",'Investigator Data'!B14) -> 20240407_S4_C | D34: =IF('Investigator Data'!C14="",$D$8,'Investigator Data'!C14) -> 30 | E34: 30.028 | F34: =F33+1 -> 18
A35: ="IC"&COVER!C$15&COVER!C$23&"-"&COVER!C$22&F35 -> IC15N240610-1019 | B35: B7 | C35: =IF('Investigator Data'!B15="","",'Investigator Data'!B15) -> 20240407_S4_D | D35: =IF('Investigator Data'!C15="",$D$8,'Investigator Data'!C15) -> 30 | E35: 29.779 | F35: =F34+1 -> 19
A36: ="IC"&COVER!C$15&COVER!C$23&"-"&COVER!C$22&F36 -> IC15N240610-1020 | B36: B8 | C36: =IF('Investigator Data'!B16="","",'Investigator Data'!B16) -> 20240407_S4_E | D36: =IF('Investigator Data'!C16="",$D$8,'Investigator Data'!C16) -> 30 | E36: 30.711 | F36: =F35+1 -> 20
A37: ="IC"&COVER!C$15&COVER!C$23&"-"&COVER!C$22&F37 -> IC15N240610-1021 | B37: B9 | C37: =IF('Investigator Data'!B17="","","R2-"&'Investigator Data'!B17) -> R2-20240407_S4_F | D37: =IF('Investigator Data'!C17="",$D$8,'Investigator Data'!C17) -> 30 | E37: 30.091 | F37: =F36+1 -> 21
A38: ="IC"&COVER!C$15&COVER!C$23&"-"&COVER!C$22&F38 -> IC15N240610-1022 | B38: B10 | C38: =IF('Investigator Data'!B17="","","R2-"&'Investigator Data'!B17) -> R2-20240407_S4_F | D38: =IF('Investigator Data'!C17="",$D$8,'Investigator Data'!C17) -> 30 | E38: 30.038 | F38: =F37+1 -> 22
A39: ="IC"&COVER!C$15&COVER!C$23&"-"&COVER!C$22&F39 -> IC15N240610-1023 | B39: B11 | C39: =IF('Investigator Data'!B18="","",'Investigator Data'!B18) -> 20240407_S4_G | D39: =IF('Investigator Data'!C18="",$D$8,'Investigator Data'!C18) -> 30 | E39: 30.295 | F39: =F38+1 -> 23
A40: ="IC"&COVER!C$15&COVER!C$23&"-"&COVER!C$22&F40 -> IC15N240610-1024 | B40: B12 | C40: =IF('Investigator Data'!B19="","",'Investigator Data'!B19) -> 20240407_S4_H | D40: =IF('Investigator Data'!C19="",$D$8,'Investigator Data'!C19) -> 30 | E40: 29.72 | F40: =F39+1 -> 24
A41: ="IC"&COVER!C$15&COVER!C$23&"-"&COVER!C$22&F41 -> IC15N240610-1025 | B41: C1 | C41: =IF('Investigator Data'!B20="","",'Investigator Data'!B20) -> 20240407_S4_I | D41: =IF('Investigator Data'!C20="",$D$8,'Investigator Data'!C20) -> 30 | E41: 30.496 | F41: =F40+1 -> 25
...

Sheet Investigator QA Data
E2: FILE NAME: | F2: =COVER!C2 -> IC15N-240610-10KansasROAR-4
A4: Quality Assurance data for Carbon: | E4: d13C | I4: %C | M4: Precision of carbon data
C5: Sample | D5: Actual | E5: Meas. | F5: Var. | G5: s.d. | H5: Actual | I5: Meas. | J5: Var. | K5: r. s.d. | L5: N | M5: d13C | O5: =IF(SUM(L7:L11)<2,"",SQRT((SUMPRODUCT(F6:F11,L6:L11))/SUM(L6:L11))) -> #DIV/0!
A6: NIST Certified Isotope Standard - QC | C6: ='ISIRF 13C'!A7 -> NBS 1572 Citrus Leaf | D6: ='ISIRF 13C'!C7 -> 0 | E6: ='ISIRF 13C'!B33 -> 0 | F6: ='ISIRF 13C'!C33 -> 0 | G6: ='ISIRF 13C'!D33 -> 0 | H6: ='ISIRF 13C'!D7 -> 0 | I6: ='ISIRF 13C'!E33 -> 0 | J6: ='ISIRF 13C'!F33 -> 0 | K6: ='ISIRF 13C'!G33 -> #DIV/0! | L6: ='ISIRF 13C'!H33 -> 3 | M6: [C] % | O6: =AVERAGE(K6:K11) -> #DIV/0!
A7: Conc Cal Std - Isotope QC Std | C7: ='ISIRF 13C'!D11 -> ISIRF Ulva | D7: ='ISIRF 13C'!C4 -> 0 | E7: ='ISIRF 13C'!B30 -> 0 | F7: ='ISIRF 13C'!C30 -> 0 | G7: ='ISIRF 13C'!D30 -> 0 | H7: ='ISIRF 13C'!D4 -> 0 | I7: ='ISIRF 13C'!E30 -> 0 | J7: ='ISIRF 13C'!F30 -> 0 | K7: ='ISIRF 13C'!G30 -> #DIV/0! | L7: ='ISIRF 13C'!H30 -> 5 | M7: Accuracy of carbon data
A8: Conc QC Std - Isotope High Cal Std | C8: ='ISIRF 13C'!A5 -> ISIRF Chitin | D8: ='ISIRF 13C'!C5 -> 0 | E8: ='ISIRF 13C'!B31 -> 0 | F8: ='ISIRF 13C'!C31 -> 0 | G8: ='ISIRF 13C'!D31 -> 0 | H8: ='ISIRF 13C'!D5 -> 0 | I8: ='ISIRF 13C'!E31 -> 0 | J8: ='ISIRF 13C'!F31 -> 0 | K8: ='ISIRF 13C'!G31 -> #DIV/0! | L8: ='ISIRF 13C'!H31 -> 3 | M8: d13C | O8: =IF(COUNT(E6:E7)=0,"",D6-E6) -> 0
A9: Conc QC Std - Isotope Low Cal Std | C9: ='ISIRF 13C'!A6 -> ISIRF Bamboo | D9: ='ISIRF 13C'!C6 -> 0 | E9: ='ISIRF 13C'!B32 -> 0 | F9: ='ISIRF 13C'!C32 -> 0 | G9: ='ISIRF 13C'!D32 -> 0 | H9: ='ISIRF 13C'!D6 -> 0 | I9: ='ISIRF 13C'!E32 -> 0 | J9: ='ISIRF 13C'!F32 -> 0 | K9: ='ISIRF 13C'!G32 -> #DIV/0! | L9: ='ISIRF 13C'!H32 -> 3 | M9: [C] % | O9: =(H6-I6) -> 0
A10: Replicate Sample 1 | C10: ='Investigator Data'!B4 -> 20240407_S2_J | E10: ='ISIRF 13C'!B28 -> #DIV/0! | F10: ='ISIRF 13C'!C28 -> #DIV/0! | G10: ='ISIRF 13C'!D28 -> #DIV/0! | I10: ='ISIRF 13C'!E28 -> #DIV/0! | J10: ='ISIRF 13C'!F28 -> #DIV/0! | K10: ='ISIRF 13C'!G28 -> #DIV/0! | L10: ='ISIRF 13C'!H28 -> 0
A11: Replicate Sample 2 | C11: ='Investigator Data'!B17 -> 20240407_S4_F | E11: ='ISIRF 13C'!B29 -> #DIV/0! | F11: ='ISIRF 13C'!C29 -> #DIV/0! | G11: ='ISIRF 13C'!D29 -> #DIV/0! | I11: ='ISIRF 13C'!E29 -> #DIV/0! | J11: ='ISIRF 13C'!F29 -> #DIV/0! | K11: ='ISIRF 13C'!G29 -> #DIV/0! | L11: ='ISIRF 13C'!H29 -> 0
A13: Quality Assurance Data for Nitrogen: | E13: d15N | I13: %N | M13: Precision of nitrogen data
C14: Sample | D14: Actual | E14: Meas. | F14: Var. | G14: s.d. | H14: Actual | I14: Meas. | J14: Var. | K14: r.s.d. | L14: N | M14: d15N | O14: =IF(SUM(L16:L20)<2,"",SQRT(SUMPRODUCT(F15:F20,L15:L20)/SUM(L15:L20))) -> #DIV/0!
A15: NIST Certified Isotope Standard - QC | C15: ='ISIRF 15N'!A7 -> NBS 1572 Citrus Leaf | D15: ='ISIRF 15N'!C7 -> 0 | E15: ='ISIRF 15N'!B33 -> 0 | F15: ='ISIRF 15N'!C33 -> 0 | G15: ='ISIRF 15N'!D33 -> 0 | H15: ='ISIRF 15N'!D7 -> 0 | I15: ='ISIRF 15N'!E33 -> 0 | J15: ='ISIRF 15N'!F33 -> 0 | K15: ='ISIRF 15N'!G33 -> #DIV/0! | L15: ='ISIRF 15N'!H33 -> 3 | M15: [N] % | O15: =AVERAGE(K15:K20) -> #DIV/0!
A16: Conc Cal Std - Isotope QC Std | C16: ='ISIRF 15N'!A4 -> ISIRF Ulva | D16: ='ISIRF 15N'!C4 -> 0 | E16: ='ISIRF 15N'!B30 -> 0 | F16: ='ISIRF 15N'!C30 -> 0 | G16: ='ISIRF 15N'!D30 -> 0 | H16: ='ISIRF 15N'!D4 -> 0 | I16: ='ISIRF 15N'!E30 -> 0 | J16: ='ISIRF 15N'!F30 -> 0 | K16: ='ISIRF 15N'!G30 -> #DIV/0! | L16: ='ISIRF 15N'!H30 -> 5 | M16: Accuracy of nitrogen data
A17: Conc QC Std - Isotope High Cal Std | C17: ='ISIRF 15N'!A5 -> ISIRF Chitin | D17: ='ISIRF 15N'!C5 -> 0 | E17: ='ISIRF 15N'!B31 -> 0 | F17: ='ISIRF 15N'!C31 -> 0 | G17: ='ISIRF 15N'!D31 -> 0 | H17: ='ISIRF 15N'!D5 -> 0 | I17: ='ISIRF 15N'!E31 -> 0 | J17: ='ISIRF 15N'!F31 -> 0 | K17: ='ISIRF 15N'!G31 -> #DIV/0! | L17: ='ISIRF 15N'!H31 -> 3 | M17: d15N | O17: =IF(COUNT(E15:E16)=0,"",D15-E15) -> 0
A18: Conc QC Std - Isotope Low Cal Std | C18: ='ISIRF 15N'!A6 -> ISIRF Bamboo | D18: ='ISIRF 15N'!C6 -> 0 | E18: ='ISIRF 15N'!B32 -> 0 | F18: ='ISIRF 15N'!C32 -> 0 | G18: ='ISIRF 15N'!D32 -> 0 | H18: ='ISIRF 15N'!D6 -> 0 | I18: ='ISIRF 15N'!E32 -> 0 | J18: ='ISIRF 15N'!F32 -> 0 | K18: ='ISIRF 15N'!G32 -> #DIV/0! | L18: ='ISIRF 15N'!H32 -> 3 | M18: [N] % | O18: =IF(COUNT(I15,I17:I18)=0,"",H15-I15) -> 0
A19: Replicate Sample 1 | C19: ='Investigator Data'!B4 -> 20240407_S2_J | E19: ='ISIRF 15N'!B28 -> #DIV/0! | F19: ='ISIRF 15N'!C28 -> #DIV/0! | G19: ='ISIRF 15N'!D28 -> #DIV/0! | I19: ='ISIRF 15N'!E28 -> #DIV/0! | J19: ='ISIRF 15N'!F28 -> #DIV/0! | K19: ='ISIRF 15N'!G28 -> #DIV/0! | L19: ='ISIRF 15N'!H28 -> 0
A20: Replicate Sample 2 | C20: ='Investigator Data'!B17 -> 20240407_S4_F | E20: ='ISIRF 15N'!B29 -> #DIV/0! | F20: ='ISIRF 15N'!C29 -> #DIV/0! | G20: ='ISIRF 15N'!D29 -> #DIV/0! | I20: ='ISIRF 15N'!E29 -> #DIV/0! | J20: ='ISIRF 15N'!F29 -> #DIV/0! | K20: ='ISIRF 15N'!G29 -> #DIV/0! | L20: ='ISIRF 15N'!H29 -> 0
A22: Quality Assurance Data for Sulfur: | E22: d34S | I22: %S | M22: Precision of Sulfur data
C23: Sample | D23: Actual | E23: Meas. | F23: Var. | G23: s.d. | H23: Actual | I23: Meas. | J23: Var. | K23: s.d. | L23: N | M23: d34S | O23: =IF(SUM(L25:L29)<2,"",SQRT(SUMPRODUCT(F24:F29,L24:L29)/SUM(L24:L29)))
A24: NIST Certified Isotope Standard - QC | M24: [S] % | O24: =IF(SUM(L25:L29)<2,"",SQRT(SUMPRODUCT(J24:J29,L24:L29)/SUM(L24:L29)))
A25: Conc Cal Std - Isotope QC Std | M25: Accuracy of Sulfur data
A26: Conc QC Std - Isotope High Cal Std | M26: d34S | O26: =IF(COUNT(E24:E25)=0,"",D24-E24)
A27: Conc QC Std - Isotope Low Cal Std | M27: [S] % | O27: =IF(COUNT(I24,I26:I27)=0,"",AVERAGE(H24-I24,H26-I26,H27-I27))
A28: Replicate Sample 1
A29: Replicate Sample 2
A31: Standard and replicate data
A32: Run date | B32: File name | D32: Standard | E32: Run type | F32: Seq # | G32: Wt. (mg) | H32: Mass 28 nAmp | I32: Mass 28 Area | J32: %N | K32: δ15N | L32: Mass 44 nAmp | M32: Mass 44 Area | N32: %C | O32: δ13C | Q32: Notes
A33: ='ISIRF RAW'!$B$2 -> 0 | B33: ='ISIRF 15N'!B11 -> 0 | D33: ='ISIRF 15N'!D11 -> ISIRF Ulva | E33: ='ISIRF 15N'!E11 -> QC.STD | F33: ='ISIRF 15N'!F11 -> 0 | G33: ='ISIRF 15N'!G11 -> 0 | H33: ='ISIRF 15N'!H11 -> 0 | I33: ='ISIRF 15N'!I11 -> 0 | J33: ='ISIRF 15N'!J11 -> 0 | K33: ='ISIRF 15N'!K11 -> 0 | L33: ='ISIRF 13C'!H11 -> 0 | M33: ='ISIRF 13C'!I11 -> 0 | N33: ='ISIRF 13C'!J11 -> 0 | O33: ='ISIRF 13C'!K11 -> 0 | P33: ='ISIRF 15N'!L11&'ISIRF 13C'!L11 | R33: =IF(COUNTA('ISIRF 15N'!L11)=1,"See ISIRF 15N","")
A34: ='ISIRF RAW'!$B$2 -> 0 | B34: ='ISIRF 15N'!B12 -> 0 | D34: ='ISIRF 15N'!D12 -> ISIRF Ulva | E34: ='ISIRF 15N'!E12 -> QC.STD | F34: ='ISIRF 15N'!F12 -> 0 | G34: ='ISIRF 15N'!G12 -> 0 | H34: ='ISIRF 15N'!H12 -> 0 | I34: ='ISIRF 15N'!I12 -> 0 | J34: ='ISIRF 15N'!J12 -> 0 | K34: ='ISIRF 15N'!K12 -> 0 | L34: ='ISIRF 13C'!H12 -> 0 | M34: ='ISIRF 13C'!I12 -> 0 | N34: ='ISIRF 13C'!J12 -> 0 | O34: ='ISIRF 13C'!K12 -> 0 | P34: ='ISIRF 15N'!L12&'ISIRF 13C'!L12 | R34: =IF(COUNTA('ISIRF 15N'!L12)=1,"See ISIRF 15N","")
A35: ='ISIRF RAW'!$B$2 -> 0 | B35: ='ISIRF 15N'!B13 -> 0 | D35: ='ISIRF 15N'!D13 -> ISIRF Ulva | E35: ='ISIRF 15N'!E13 -> QC.STD | F35: ='ISIRF 15N'!F13 -> 0 | G35: ='ISIRF 15N'!G13 -> 0 | H35: ='ISIRF 15N'!H13 -> 0 | I35: ='ISIRF 15N'!I13 -> 0 | J35: ='ISIRF 15N'!J13 -> 0 | K35: ='ISIRF 15N'!K13 -> 0 | L35: ='ISIRF 13C'!H13 -> 0 | M35: ='ISIRF 13C'!I13 -> 0 | N35: ='ISIRF 13C'!J13 -> 0 | O35: ='ISIRF 13C'!K13 -> 0 | P35: ='ISIRF 15N'!L13&'ISIRF 13C'!L13 | R35: =IF(COUNTA('ISIRF 15N'!L13)=1,"See ISIRF 15N","")
A36: ='ISIRF RAW'!$B$2 -> 0 | B36: ='ISIRF 15N'!B14 -> 0 | D36: ='ISIRF 15N'!D14 -> ISIRF Ulva | E36: ='ISIRF 15N'!E14 -> QC.STD | F36: ='ISIRF 15N'!F14 -> 0 | G36: ='ISIRF 15N'!G14 -> 0 | H36: ='ISIRF 15N'!H14 -> 0 | I36: ='ISIRF 15N'!I14 -> 0 | J36: ='ISIRF 15N'!J14 -> 0 | K36: ='ISIRF 15N'!K14 -> 0 | L36: ='ISIRF 13C'!H14 -> 0 | M36: ='ISIRF 13C'!I14 -> 0 | N36: ='ISIRF 13C'!J14 -> 0 | O36: ='ISIRF 13C'!K14 -> 0 | P36: ='ISIRF 15N'!L14&'ISIRF 13C'!L14 | R36: =IF(COUNTA('ISIRF 15N'!L14)=1,"See ISIRF 15N","")
A37: ='ISIRF RAW'!$B$2 -> 0 | B37: ='ISIRF 15N'!B15 -> 0 | D37: ='ISIRF 15N'!D15 -> ISIRF Ulva | E37: ='ISIRF 15N'!E15 -> QC.STD | F37: ='ISIRF 15N'!F15 -> 0 | G37: ='ISIRF 15N'!G15 -> 0 | H37: ='ISIRF 15N'!H15 -> 0 | I37: ='ISIRF 15N'!I15 -> 0 | J37: ='ISIRF 15N'!J15 -> 0 | K37: ='ISIRF 15N'!K15 -> 0 | L37: ='ISIRF 13C'!H15 -> 0 | M37: ='ISIRF 13C'!I15 -> 0 | N37: ='ISIRF 13C'!J15 -> 0 | O37: ='ISIRF 13C'!K15 -> 0 | P37: ='ISIRF 15N'!L15&'ISIRF 13C'!L15 | R37: =IF(COUNTA('ISIRF 15N'!L15)=1,"See ISIRF 15N","")
A38: ='ISIRF RAW'!$B$2 -> 0 | B38: ='ISIRF 15N'!B16 -> 0 | D38: ='ISIRF 15N'!D16 -> ISIRF Chitin | E38: ='ISIRF 15N'!E16 -> Cal-H.STD | F38: ='ISIRF 15N'!F16 -> 0 | G38: ='ISIRF 15N'!G16 -> 0 | H38: ='ISIRF 15N'!H16 -> 0 | I38: ='ISIRF 15N'!I16 -> 0 | J38: ='ISIRF 15N'!J16 -> 0 | K38: ='ISIRF 15N'!K16 -> 0 | L38: ='ISIRF 13C'!H16 -> 0 | M38: ='ISIRF 13C'!H16 -> 0 | N38: ='ISIRF 13C'!J16 -> 0 | O38: ='ISIRF 13C'!K16 -> 0
A39: ='ISIRF RAW'!$B$2 -> 0 | B39: ='ISIRF 15N'!B17 -> 0 | D39: ='ISIRF 15N'!D17 -> ISIRF Chitin | E39: ='ISIRF 15N'!E17 -> Cal-H.STD | F39: ='ISIRF 15N'!F17 -> 0 | G39: ='ISIRF 15N'!G17 -> 0 | H39: ='ISIRF 15N'!H17 -> 0 | I39: ='ISIRF 15N'!I17 -> 0 | J39: ='ISIRF 15N'!J17 -> 0 | K39: ='ISIRF 15N'!K17 -> 0 | L39: ='ISIRF 13C'!H17 -> 0 | M39: ='ISIRF 13C'!I17 -> 0 | N39: ='ISIRF 13C'!J17 -> 0 | O39: ='ISIRF 13C'!K17 -> 0
A40: ='ISIRF RAW'!$B$2 -> 0 | B40: ='ISIRF 15N'!B18 -> 0 | D40: ='ISIRF 15N'!D18 -> ISIRF Chitin | E40: ='ISIRF 15N'!E18 -> Cal-H.STD | F40: ='ISIRF 15N'!F18 -> 0 | G40: ='ISIRF 15N'!G18 -> 0 | H40: ='ISIRF 15N'!H18 -> 0 | I40: ='ISIRF 15N'!I18 -> 0 | J40: ='ISIRF 15N'!J18 -> 0 | K40: ='ISIRF 15N'!K18 -> 0 | L40: ='ISIRF 13C'!H18 -> 0 | M40: ='ISIRF 13C'!I18 -> 0 | N40: ='ISIRF 13C'!J18 -> 0 | O40: ='ISIRF 13C'!K18 -> 0
A41: ='ISIRF RAW'!$B$2 -> 0 | B41: ='ISIRF 15N'!B19 -> 0 | D41: ='ISIRF 15N'!D19 -> ISIRF Bamboo | E41: ='ISIRF 15N'!E19 -> Cal-L.STD | F41: ='ISIRF 15N'!F19 -> 0 | G41: ='ISIRF 15N'!G19 -> 0 | H41: ='ISIRF 15N'!H19 -> 0 | I41: ='ISIRF 15N'!I19 -> 0 | J41: ='ISIRF 15N'!J19 -> 0 | K41: ='ISIRF 15N'!K19 -> 0 | L41: ='ISIRF 13C'!H19 -> 0 | M41: ='ISIRF 13C'!I19 -> 0 | N41: ='ISIRF 13C'!J19 -> 0 | O41: ='ISIRF 13C'!K19 -> 0
A42: ='ISIRF RAW'!$B$2 -> 0 | B42: ='ISIRF 15N'!B20 -> 0 | D42: ='ISIRF 15N'!D20 -> ISIRF Bamboo | E42: ='ISIRF 15N'!E20 -> Cal-L.STD | F42: ='ISIRF 15N'!F20 -> 0 | G42: ='ISIRF 15N'!G20 -> 0 | H42: ='ISIRF 15N'!H20 -> 0 | I42: ='ISIRF 15N'!I20 -> 0 | J42: ='ISIRF 15N'!J20 -> 0 | K42: ='ISIRF 15N'!K20 -> 0 | L42: ='ISIRF 13C'!H20 -> 0 | M42: ='ISIRF 13C'!I20 -> 0 | N42: ='ISIRF 13C'!J20 -> 0 | O42: ='ISIRF 13C'!K20 -> 0
A43: ='ISIRF RAW'!$B$2 -> 0 | B43: ='ISIRF 15N'!B21 -> 0 | D43: ='ISIRF 15N'!D21 -> ISIRF Bamboo | E43: ='ISIRF 15N'!E21 -> Cal-L.STD | F43: ='ISIRF 15N'!F21 -> 0 | G43: ='ISIRF 15N'!G21 -> 0 | H43: ='ISIRF 15N'!H21 -> 0 | I43: ='ISIRF 15N'!I21 -> 0 | J43: ='ISIRF 15N'!J21 -> 0 | K43: ='ISIRF 15N'!K21 -> 0 | L43: ='ISIRF 13C'!H21 -> 0 | M43: ='ISIRF 13C'!I21 -> 0 | N43: ='ISIRF 13C'!J21 -> 0 | O43: ='ISIRF 13C'!K21 -> 0
A44: ='ISIRF RAW'!$B$2 -> 0 | B44: ='ISIRF 15N'!B22 -> 0 | D44: ='ISIRF 15N'!D22 -> NBS 1572 Citrus Leaf | E44: ='ISIRF 15N'!E22 -> QA STD | F44: ='ISIRF 15N'!F22 -> 0 | G44: ='ISIRF 15N'!G22 -> 0 | H44: ='ISIRF 15N'!H22 -> 0 | I44: ='ISIRF 15N'!I22 -> 0 | J44: ='ISIRF 15N'!J22 -> 0 | K44: ='ISIRF 15N'!K22 -> 0 | L44: ='ISIRF 13C'!H22 -> 0 | M44: ='ISIRF 13C'!I22 -> 0 | N44: ='ISIRF 13C'!J22 -> 0 | O44: ='ISIRF 13C'!K22 -> 0
A45: ='ISIRF RAW'!$B$2 -> 0 | B45: ='ISIRF 15N'!B23 -> 0 | D45: ='ISIRF 15N'!D23 -> NBS 1572 Citrus Leaf | E45: ='ISIRF 15N'!E23 -> QA STD | F45: ='ISIRF 15N'!F23 -> 0 | G45: ='ISIRF 15N'!G23 -> 0 | H45: ='ISIRF 15N'!H23 -> 0 | I45: ='ISIRF 15N'!I23 -> 0 | J45: ='ISIRF 15N'!J23 -> 0 | K45: ='ISIRF 15N'!K23 -> 0 | L45: ='ISIRF 13C'!H23 -> 0 | M45: ='ISIRF 13C'!I23 -> 0 | N45: ='ISIRF 13C'!J23 -> 0 | O45: ='ISIRF 13C'!K23 -> 0
...

Sheet ISIRF RAW
A1: ISIRF USE ONLY
A2: DATE RUN:
A3: ANALYST: | D3: FILE NAME: | E3: =COVER!C2 -> IC15N-240610-10KansasROAR-4
A4: METHOD:
A5: Sample Name | B5: Line | C5: Sample Wt (mg) | D5: Mass 28 nA | E5: N2 Area | F5: Mass 44 nA | G5: CO2 Area | H5: Mass 64 nA | I5: SO2 Area | J5: Wt % N | K5: 15N ‰ Air | L5: 15N ‰ Air Corrected | M5: Wt % C | N5: 13C ‰ pdb | O5: 13C ‰ pdb Corrected | P5: Wt % S | Q5: 34S ‰ pdb | R5: 34S ‰ pdb Corrected | S5: Date | T5: Filename
A6: ='Weigh Sheet'!C17 -> blank
A7: ='Weigh Sheet'!C18 -> blank
A8: ='Weigh Sheet'!C19 -> ISIRF Ulva
A9: ='Weigh Sheet'!C20 -> ISIRF Chitin
A10: ='Weigh Sheet'!C21 -> ISIRF Bamboo
A11: ='Weigh Sheet'!C22 -> NBS 1572 Citrus Leaf
A12: ='Weigh Sheet'!C23 -> R1-20240407_S2_J
A13: ='Weigh Sheet'!C24 -> 20240407_S3_A
A14: ='Weigh Sheet'!C25 -> 20240407_S3_B
A15: ='Weigh Sheet'!C26 -> 20240407_S3_C
A16: ='Weigh Sheet'!C27 -> 20240407_S3_D
A17: ='Weigh Sheet'!C28 -> 20240407_S3_E
... A61: ='Weigh Sheet'!C72 -> NBS 1572 Citrus Leaf
A62: Standard | B62: Run Type | C62: Actual d15N | D62: %N | E62: Actual d13C | F62: %C | G62: Actual d34S | H62: %S | I62: Slope d15N | J62: Intrcpt | K62: Slope d13C | L62: Intrcpt | M62: Slope d34S | N62: Intrcpt

Sheet ISIRF 15N
A1: FILE NAME: | B1: =COVER!C2 -> IC15N-240610-10KansasROAR-4
A3: Standard | B3: Run Type | C3: δ15N | D3: %N
A4: ='Weigh Sheet'!C9 -> ISIRF Ulva | B4: QC.STD | C4: ='ISIRF RAW'!C63 -> 0 | D4: ='ISIRF RAW'!D63 -> 0
A5: ='Weigh Sheet'!C10 -> ISIRF Chitin | B5: Cal-H.STD | C5: ='ISIRF RAW'!C64 -> 0 | D5: ='ISIRF RAW'!D64 -> 0
A6: ='Weigh Sheet'!C11 -> ISIRF Bamboo | B6: Cal-L.STD | C6: ='ISIRF RAW'!C65 -> 0 | D6: ='ISIRF RAW'!D65 -> 0
A7: ='Weigh Sheet'!C12 -> NBS 1572 Citrus Leaf | B7: Check QC | C7: ='ISIRF RAW'!C66 -> 0 | D7: ='ISIRF RAW'!D66 -> 0
A9: Nitrogen Standards
A10: Run date | B10: File name | D10: Standard | E10: Run type | F10: Seq # | G10: Wt. (mg) | H10: Mass 28 nAmp | I10: N2 Area | J10: %N | K10: δ15N | L10: Notes
A11: ='ISIRF RAW'!S8 -> 0 | B11: ='ISIRF RAW'!T8 -> 0 | D11: ='ISIRF RAW'!A8 -> ISIRF Ulva | E11: =$B$4 -> QC.STD | F11: ='ISIRF RAW'!B8 -> 0 | G11: ='ISIRF RAW'!C8 -> 0 | H11: ='ISIRF RAW'!D8 -> 0 | I11: ='ISIRF RAW'!E8 -> 0 | J11: ='ISIRF RAW'!J8 -> 0 | K11: ='ISIRF RAW'!L8 -> 0
A12: ='ISIRF RAW'!S21 -> 0 | B12: ='ISIRF RAW'!T21 -> 0 | D12: ='ISIRF RAW'!A21 -> ISIRF Ulva | E12: =$B$4 -> QC.STD | F12: ='ISIRF RAW'!B21 -> 0 | G12: ='ISIRF RAW'!C21 -> 0 | H12: ='ISIRF RAW'!D21 -> 0 | I12: ='ISIRF RAW'!E21 -> 0 | J12: ='ISIRF RAW'!J21 -> 0 | K12: ='ISIRF RAW'!L21 -> 0
A13: ='ISIRF RAW'!S33 -> 0 | B13: ='ISIRF RAW'!T33 -> 0 | D13: ='ISIRF RAW'!A33 -> ISIRF Ulva | E13: =$B$4 -> QC.STD | F13: ='ISIRF RAW'!B33 -> 0 | G13: ='ISIRF RAW'!C33 -> 0 | H13: ='ISIRF RAW'!D33 -> 0 | I13: ='ISIRF RAW'!E33 -> 0 | J13: ='ISIRF RAW'!J33 -> 0 | K13: ='ISIRF RAW'!L33 -> 0
A14: ='ISIRF RAW'!S46 -> 0 | B14: ='ISIRF RAW'!T46 -> 0 | D14: ='ISIRF RAW'!A46 -> ISIRF Ulva | E14: =$B$4 -> QC.STD | F14: ='ISIRF RAW'!B46 -> 0 | G14: ='ISIRF RAW'!C46 -> 0 | H14: ='ISIRF RAW'!D46 -> 0 | I14: ='ISIRF RAW'!E46 -> 0 | J14: ='ISIRF RAW'!J46 -> 0 | K14: ='ISIRF RAW'!L46 -> 0
A15: ='ISIRF RAW'!S58 -> 0 | B15: ='ISIRF RAW'!T58 -> 0 | D15: ='ISIRF RAW'!A58 -> ISIRF Ulva | E15: =$B$4 -> QC.STD | F15: ='ISIRF RAW'!B58 -> 0 | G15: ='ISIRF RAW'!C58 -> 0 | H15: ='ISIRF RAW'!D58 -> 0 | I15: ='ISIRF RAW'!E58 -> 0 | J15: ='ISIRF RAW'!J58 -> 0 | K15: ='ISIRF RAW'!L58 -> 0
A16: ='ISIRF RAW'!S9 -> 0 | B16: ='ISIRF RAW'!T9 -> 0 | D16: ='ISIRF RAW'!A9 -> ISIRF Chitin | E16: =B$5 -> Cal-H.STD | F16: ='ISIRF RAW'!B9 -> 0 | G16: ='ISIRF RAW'!C9 -> 0 | H16: ='ISIRF RAW'!D9 -> 0 | I16: ='ISIRF RAW'!E9 -> 0 | J16: ='ISIRF RAW'!J9 -> 0 | K16: ='ISIRF RAW'!L9 -> 0
A17: ='ISIRF RAW'!S34 -> 0 | B17: ='ISIRF RAW'!T34 -> 0 | D17: ='ISIRF RAW'!A34 -> ISIRF Chitin | E17: =B$5 -> Cal-H.STD | F17: ='ISIRF RAW'!B34 -> 0 | G17: ='ISIRF RAW'!C34 -> 0 | H17: ='ISIRF RAW'!D34 -> 0 | I17: ='ISIRF RAW'!E34 -> 0 | J17: ='ISIRF RAW'!J34 -> 0 | K17: ='ISIRF RAW'!L34 -> 0
A18: ='ISIRF RAW'!S59 -> 0 | B18: ='ISIRF RAW'!T59 -> 0 | D18: ='ISIRF RAW'!A59 -> ISIRF Chitin | E18: =B$5 -> Cal-H.STD | F18: ='ISIRF RAW'!B59 -> 0 | G18: ='ISIRF RAW'!C59 -> 0 | H18: ='ISIRF RAW'!D59 -> 0 | I18: ='ISIRF RAW'!E59 -> 0 | J18: ='ISIRF RAW'!J59 -> 0 | K18: ='ISIRF RAW'!L59 -> 0
A19: ='ISIRF RAW'!S10 -> 0 | B19: ='ISIRF RAW'!T10 -> 0 | D19: ='ISIRF RAW'!A10 -> ISIRF Bamboo | E19: =B$6 -> Cal-L.STD | F19: ='ISIRF RAW'!B10 -> 0 | G19: ='ISIRF RAW'!C10 -> 0 | H19: ='ISIRF RAW'!D10 -> 0 | I19: ='ISIRF RAW'!E10 -> 0 | J19: ='ISIRF RAW'!J10 -> 0 | K19: ='ISIRF RAW'!L10 -> 0
A20: ='ISIRF RAW'!S35 -> 0 | B20: ='ISIRF RAW'!T35 -> 0 | D20: ='ISIRF RAW'!A35 -> ISIRF Bamboo | E20: =B$6 -> Cal-L.STD | F20: ='ISIRF RAW'!B35 -> 0 | G20: ='ISIRF RAW'!C35 -> 0 | H20: ='ISIRF RAW'!D35 -> 0 | I20: ='ISIRF RAW'!E35 -> 0 | J20: ='ISIRF RAW'!J35 -> 0 | K20: ='ISIRF RAW'!L35 -> 0
A21: ='ISIRF RAW'!S60 -> 0 | B21: ='ISIRF RAW'!T60 -> 0 | D21: ='ISIRF RAW'!A60 -> ISIRF Bamboo | E21: =B$6 -> Cal-L.STD | F21: ='ISIRF RAW'!B60 -> 0 | G21: ='ISIRF RAW'!C60 -> 0 | H21: ='ISIRF RAW'!D60 -> 0 | I21: ='ISIRF RAW'!E60 -> 0 | J21: ='ISIRF RAW'!J60 -> 0 | K21: ='ISIRF RAW'!L60 -> 0
A22: ='ISIRF RAW'!S11 -> 0 | B22: ='ISIRF RAW'!T11 -> 0 | D22: ='ISIRF RAW'!A11 -> NBS 1572 Citrus Leaf | E22: QA STD | F22: ='ISIRF RAW'!B11 -> 0 | G22: ='ISIRF RAW'!C11 -> 0 | H22: ='ISIRF RAW'!D11 -> 0 | I22: ='ISIRF RAW'!E11 -> 0 | J22: ='ISIRF RAW'!J11 -> 0 | K22: ='ISIRF RAW'!L11 -> 0
A23: ='ISIRF RAW'!S36 -> 0 | B23: ='ISIRF RAW'!T36 -> 0 | D23: ='ISIRF RAW'!A36 -> NBS 1572 Citrus Leaf | E23: QA STD | F23: ='ISIRF RAW'!B36 -> 0 | G23: ='ISIRF RAW'!C36 -> 0 | H23: ='ISIRF RAW'!D36 -> 0 | I23: ='ISIRF RAW'!E36 -> 0 | J23: ='ISIRF RAW'!J36 -> 0 | K23: ='ISIRF RAW'!L36 -> 0
A24: ='ISIRF RAW'!S61 -> 0 | B24: ='ISIRF RAW'!T61 -> 0 | D24: ='ISIRF RAW'!A61 -> NBS 1572 Citrus Leaf | E24: QA STD | F24: ='ISIRF RAW'!B61 -> 0 | G24: ='ISIRF RAW'!C61 -> 0 | H24: ='ISIRF RAW'!D61 -> 0 | I24: ='ISIRF RAW'!E61 -> 0 | J24: ='ISIRF RAW'!J61 -> 0 | K24: ='ISIRF RAW'!L61 -> 0
A26: QA Summary 15N: | C26: d15N | F26: %N | H26: N
B27: X | C27: var. | D27: s.d. | E27: X | F27: var | G27: r.s.d.
A28: REP1 (‰) | B28: =AVERAGE('ISIRF RAW'!L12,'ISIRF RAW'!L56) -> #DIV/0! | C28: =VAR('ISIRF RAW'!L12,'ISIRF RAW'!L56) -> #DIV/0! | D28: =STDEV('ISIRF RAW'!L12,'ISIRF RAW'!L56) -> #DIV/0! | E28: =AVERAGE('ISIRF RAW'!J12,'ISIRF RAW'!J56) -> #DIV/0! | F28: =VAR('ISIRF RAW'!J12,'ISIRF RAW'!J56) -> #DIV/0! | G28: =(STDEV('ISIRF RAW'!J12,'ISIRF RAW'!J56))/E28 -> #DIV/0! | H28: =COUNT('ISIRF RAW'!J12,'ISIRF RAW'!J56) -> 0
A29: REP2 (‰) | B29: =AVERAGE('ISIRF RAW'!L26:L27) -> #DIV/0! | C29: =VAR('ISIRF RAW'!L26:L27) -> #DIV/0! | D29: =STDEV('ISIRF RAW'!L26:L27) -> #DIV/0! | E29: =AVERAGE('ISIRF RAW'!J26:J27) -> #DIV/0! | F29: =VAR('ISIRF RAW'!J26:J27) -> #DIV/0! | G29: =(STDEV('ISIRF RAW'!J26:J27))/E29 -> #DIV/0! | H29: =COUNT('ISIRF RAW'!J26:J27) -> 0
A30: =B4 -> QC.STD | B30: =AVERAGE(K11:K15) -> 0 | C30: =VAR(K11:K15) -> 0 | D30: =STDEV(K11:K15) -> 0 | E30: =AVERAGE(J11:J15) -> 0 | F30: =VAR(J11:J15) -> 0 | G30: =(STDEV(J11:J15))/E30 -> #DIV/0! | H30: =COUNT(J11:J15) -> 5
A31: =B5 -> Cal-H.STD | B31: =AVERAGE(K16:K18) -> 0 | C31: =VAR(K16:K18) -> 0 | D31: =STDEV(K16:K18) -> 0 | E31: =AVERAGE(J16:J18) -> 0 | F31: =VAR(J16:J18) -> 0 | G31: =(STDEV(J16:J18))/E31 -> #DIV/0! | H31: =COUNT(J16:J18) -> 3
A32: =B6 -> Cal-L.STD | B32: =AVERAGE(K19:K21) -> 0 | C32: =VAR(K19:K21) -> 0 | D32: =STDEV(K19:K21) -> 0 | E32: =AVERAGE(J19:J21) -> 0 | F32: =VAR(J19:J21) -> 0 | G32: =(STDEV(J19:J21))/E32 -> #DIV/0! | H32: =COUNT(J19:J21) -> 3
A33: =B7 -> Check QC | B33: =AVERAGE(K22:K24) -> 0 | C33: =VAR(K22:K24) -> 0 | D33: =STDEV(K22:K24) -> 0 | E33: =AVERAGE(J22:J24) -> 0 | F33: =VAR(J22:J24) -> 0 | G33: =(STDEV(J22:J24))/E33 -> #DIV/0! | H33: =COUNT(J22:J24) -> 3
B34: Notes:

Sheet ISIRF 13C
A1: FILE NAME: | B1: =COVER!C2 -> IC15N-240610-10KansasROAR-4
A3: Standard | B3: Run Type | C3: Actual d13C | D3: %C
A4: ='Weigh Sheet'!C9 -> ISIRF Ulva | B4: QC.STD | C4: ='ISIRF RAW'!E63 -> 0 | D4: ='ISIRF RAW'!F63 -> 0
A5: ='Weigh Sheet'!C10 -> ISIRF Chitin | B5: Cal-H.STD | C5: ='ISIRF RAW'!E64 -> 0 | D5: ='ISIRF RAW'!F64 -> 0
A6: ='Weigh Sheet'!C11 -> ISIRF Bamboo | B6: Cal-L.STD | C6: ='ISIRF RAW'!E65 -> 0 | D6: ='ISIRF RAW'!F65 -> 0
A7: ='Weigh Sheet'!C12 -> NBS 1572 Citrus Leaf | B7: Check QC | C7: ='ISIRF RAW'!E66 -> 0 | D7: ='ISIRF RAW'!F66 -> 0
A9: Carbon Standards
A10: Run date | B10: File name | D10: Standard | E10: Run type | F10: Seq # | G10: Wt. (mg) | H10: Mass 44 nAmp | I10: CO2 Area | J10: %C | K10: δ13C | L10: Notes
A11: ='ISIRF RAW'!S8 -> 0 | B11: ='ISIRF RAW'!T8 -> 0 | D11: ='ISIRF RAW'!A8 -> ISIRF Ulva | E11: QC.STD | F11: ='ISIRF RAW'!B8 -> 0 | G11: ='ISIRF RAW'!C8 -> 0 | H11: ='ISIRF RAW'!F8 -> 0 | I11: ='ISIRF RAW'!G8 -> 0 | J11: ='ISIRF RAW'!M8 -> 0 | K11: ='ISIRF RAW'!O8 -> 0
A12: ='ISIRF RAW'!S21 -> 0 | B12: ='ISIRF RAW'!T21 -> 0 | D12: ='ISIRF RAW'!A21 -> ISIRF Ulva | E12: QC.STD | F12: ='ISIRF RAW'!B21 -> 0 | G12: ='ISIRF RAW'!C21 -> 0 | H12: ='ISIRF RAW'!F21 -> 0 | I12: ='ISIRF RAW'!G21 -> 0 | J12: ='ISIRF RAW'!M21 -> 0 | K12: ='ISIRF RAW'!O21 -> 0
A13: ='ISIRF RAW'!S33 -> 0 | B13: ='ISIRF RAW'!T33 -> 0 | D13: ='ISIRF RAW'!A33 -> ISIRF Ulva | E13: QC.STD | F13: ='ISIRF RAW'!B33 -> 0 | G13: ='ISIRF RAW'!C33 -> 0 | H13: ='ISIRF RAW'!F33 -> 0 | I13: ='ISIRF RAW'!G33 -> 0 | J13: ='ISIRF RAW'!M33 -> 0 | K13: ='ISIRF RAW'!O33 -> 0
A14: ='ISIRF RAW'!S46 -> 0 | B14: ='ISIRF RAW'!T46 -> 0 | D14: ='ISIRF RAW'!A46 -> ISIRF Ulva | E14: QC.STD | F14: ='ISIRF RAW'!B46 -> 0 | G14: ='ISIRF RAW'!C46 -> 0 | H14: ='ISIRF RAW'!F46 -> 0 | I14: ='ISIRF RAW'!G46 -> 0 | J14: ='ISIRF RAW'!M46 -> 0 | K14: ='ISIRF RAW'!O46 -> 0
A15: ='ISIRF RAW'!S58 -> 0 | B15: ='ISIRF RAW'!T58 -> 0 | D15: ='ISIRF RAW'!A58 -> ISIRF Ulva | E15: QC.STD | F15: ='ISIRF RAW'!B58 -> 0 | G15: ='ISIRF RAW'!C58 -> 0 | H15: ='ISIRF RAW'!F58 -> 0 | I15: ='ISIRF RAW'!G58 -> 0 | J15: ='ISIRF RAW'!M58 -> 0 | K15: ='ISIRF RAW'!O58 -> 0
A16: ='ISIRF RAW'!S9 -> 0 | B16: ='ISIRF RAW'!T9 -> 0 | D16: ='ISIRF RAW'!A9 -> ISIRF Chitin | E16: Cal-H.STD | F16: ='ISIRF RAW'!B9 -> 0 | G16: ='ISIRF RAW'!C9 -> 0 | H16: ='ISIRF RAW'!F9 -> 0 | I16: ='ISIRF RAW'!G9 -> 0 | J16: ='ISIRF RAW'!M9 -> 0 | K16: ='ISIRF RAW'!O9 -> 0
A17: ='ISIRF RAW'!S34 -> 0 | B17: ='ISIRF RAW'!T34 -> 0 | D17: ='ISIRF RAW'!A34 -> ISIRF Chitin | E17: Cal-H.STD | F17: ='ISIRF RAW'!B34 -> 0 | G17: ='ISIRF RAW'!C34 -> 0 | H17: ='ISIRF RAW'!F34 -> 0 | I17: ='ISIRF RAW'!G34 -> 0 | J17: ='ISIRF RAW'!M34 -> 0 | K17: ='ISIRF RAW'!O34 -> 0
A18: ='ISIRF RAW'!S59 -> 0 | B18: ='ISIRF RAW'!T59 -> 0 | D18: ='ISIRF RAW'!A59 -> ISIRF Chitin | E18: Cal-H.STD | F18: ='ISIRF RAW'!B59 -> 0 | G18: ='ISIRF RAW'!C59 -> 0 | H18: ='ISIRF RAW'!F59 -> 0 | I18: ='ISIRF RAW'!G59 -> 0 | J18: ='ISIRF RAW'!M59 -> 0 | K18: ='ISIRF RAW'!O59 -> 0
A19: ='ISIRF RAW'!S10 -> 0 | B19: ='ISIRF RAW'!T10 -> 0 | D19: ='ISIRF RAW'!A10 -> ISIRF Bamboo | E19: Cal-L.STD | F19: ='ISIRF RAW'!B10 -> 0 | G19: ='ISIRF RAW'!C10 -> 0 | H19: ='ISIRF RAW'!F10 -> 0 | I19: ='ISIRF RAW'!G10 -> 0 | J19: ='ISIRF RAW'!M10 -> 0 | K19: ='ISIRF RAW'!O10 -> 0
A20: ='ISIRF RAW'!S35 -> 0 | B20: ='ISIRF RAW'!T35 -> 0 | D20: ='ISIRF RAW'!A35 -> ISIRF Bamboo | E20: Cal-L.STD | F20: ='ISIRF RAW'!B35 -> 0 | G20: ='ISIRF RAW'!C35 -> 0 | H20: ='ISIRF RAW'!F35 -> 0 | I20: ='ISIRF RAW'!G35 -> 0 | J20: ='ISIRF RAW'!M35 -> 0 | K20: ='ISIRF RAW'!O35 -> 0
A21: ='ISIRF RAW'!S60 -> 0 | B21: ='ISIRF RAW'!T60 -> 0 | D21: ='ISIRF RAW'!A60 -> ISIRF Bamboo | E21: Cal-L.STD | F21: ='ISIRF RAW'!B60 -> 0 | G21: ='ISIRF RAW'!C60 -> 0 | H21: ='ISIRF RAW'!F60 -> 0 | I21: ='ISIRF RAW'!G60 -> 0 | J21: ='ISIRF RAW'!M60 -> 0 | K21: ='ISIRF RAW'!O60 -> 0
A22: ='ISIRF RAW'!S11 -> 0 | B22: ='ISIRF RAW'!T11 -> 0 | D22: ='ISIRF RAW'!A11 -> NBS 1572 Citrus Leaf | E22: Cal-L.STD | F22: ='ISIRF RAW'!B11 -> 0 | G22: ='ISIRF RAW'!C11 -> 0 | H22: ='ISIRF RAW'!F11 -> 0 | I22: ='ISIRF RAW'!G11 -> 0 | J22: ='ISIRF RAW'!M11 -> 0 | K22: ='ISIRF RAW'!O11 -> 0
A23: ='ISIRF RAW'!S36 -> 0 | B23: ='ISIRF RAW'!T36 -> 0 | D23: ='ISIRF RAW'!A36 -> NBS 1572 Citrus Leaf | E23: Cal-L.STD | F23: ='ISIRF RAW'!B36 -> 0 | G23: ='ISIRF RAW'!C36 -> 0 | H23: ='ISIRF RAW'!F36 -> 0 | I23: ='ISIRF RAW'!G36 -> 0 | J23: ='ISIRF RAW'!M36 -> 0 | K23: ='ISIRF RAW'!O36 -> 0
A24: ='ISIRF RAW'!S61 -> 0 | B24: ='ISIRF RAW'!T61 -> 0 | D24: ='ISIRF RAW'!A61 -> NBS 1572 Citrus Leaf | E24: Cal-L.STD | F24: ='ISIRF RAW'!B61 -> 0 | G24: ='ISIRF RAW'!C61 -> 0 | H24: ='ISIRF RAW'!F61 -> 0 | I24: ='ISIRF RAW'!G61 -> 0 | J24: ='ISIRF RAW'!M61 -> 0 | K24: ='ISIRF RAW'!O61 -> 0
A26: QA Summary 13C: | B26: 13C | E26: %C | H26: N
B27: Avg | C27: Variance | D27: s.d. | E27: X | F27: Variance | G27: r.s.d
A28: REP1 (‰) | B28: =AVERAGE('ISIRF RAW'!O12,'ISIRF RAW'!O56) -> #DIV/0! | C28: =VAR('ISIRF RAW'!O12,'ISIRF RAW'!O56) -> #DIV/0! | D28: =STDEV('ISIRF RAW'!O12,'ISIRF RAW'!O56) -> #DIV/0! | E28: =AVERAGE('ISIRF RAW'!M12,'ISIRF RAW'!M56) -> #DIV/0! | F28: =VAR('ISIRF RAW'!M12,'ISIRF RAW'!M56) -> #DIV/0! | G28: =(STDEV('ISIRF RAW'!M12,'ISIRF RAW'!M56))/E28 -> #DIV/0! | H28: =COUNT('ISIRF RAW'!M12,'ISIRF RAW'!M56) -> 0
A29: REP2 (‰) | B29: =AVERAGE('ISIRF RAW'!O26:O27) -> #DIV/0! | C29: =VAR('ISIRF RAW'!O26:O27) -> #DIV/0! | D29: =STDEV('ISIRF RAW'!O26:O27) -> #DIV/0! | E29: =AVERAGE('ISIRF RAW'!M26:M27) -> #DIV/0! | F29: =VAR('ISIRF RAW'!M26:M27) -> #DIV/0! | G29: =(STDEV('ISIRF RAW'!M26:M27))/E29 -> #DIV/0! | H29: =COUNT('ISIRF RAW'!M26:M27) -> 0
A30: =B4 -> QC.STD | B30: =AVERAGE(K11:K15) -> 0 | C30: =VAR(K11:K15) -> 0 | D30: =STDEV(K11:K15) -> 0 | E30: =AVERAGE(J11:J15) -> 0 | F30: =VAR(J11:J15) -> 0 | G30: =(STDEV(J11:J15))/E30 -> #DIV/0! | H30: =COUNT(J11:J15) -> 5
A31: =B5 -> Cal-H.STD | B31: =AVERAGE(K16:K18) -> 0 | C31: =VAR(K16:K18) -> 0 | D31: =STDEV(K16:K18) -> 0 | E31: =AVERAGE(J16:J18) -> 0 | F31: =VAR(J16:J18) -> 0 | G31: =(STDEV(J16:J18))/E31 -> #DIV/0! | H31: =COUNT(J16:J18) -> 3
A32: =B6 -> Cal-L.STD | B32: =AVERAGE(K19:K21) -> 0 | C32: =VAR(K19:K21) -> 0 | D32: =STDEV(K19:K21) -> 0 | E32: =AVERAGE(J19:J21) -> 0 | F32: =VAR(J19:J21) -> 0 | G32: =(STDEV(J19:J21))/E32 -> #DIV/0! | H32: =COUNT(J19:J21) -> 3
A33: =B7 -> Check QC | B33: =AVERAGE(K22:K24) -> 0 | C33: =VAR(K22:K24) -> 0 | D33: =STDEV(K22:K24) -> 0 | E33: =AVERAGE(J22:J24) -> 0 | F33: =VAR(J22:J24) -> 0 | G33: =(STDEV(J22:J24))/E33 -> #DIV/0! | H33: =COUNT(J22:J24) -> 3
B35: Notes:

Sheet Tables
A1: NBS/NIST | B1: Standard | C1: Targ. Wt | E1: Last Name | F1: First Name | G1: Branch | H1: ID Number | I1: Address | J1: email Address | K1: Phone
A2: B2157 Wheat Flour | B2: Wheat Flour | C2: 3 | E2: Anderson | F2: Chris | G2: EEB | H2: 11 | I2: Corvallis Anx A16 | J2: andersen.Christian@epa.gov | K2: 4791
A3: B2159 Sorghum Flour | B3: Sorghum Flour | C3: 3 | E3: Brooks | F3: Reneé | G3: EEB | H3: 8 | I3: Corvallis Bldg 74 | J3: brooks.reneej@epa.gov | K3: 4684
A4: ISIRF Bamboo | B4: Bamboo | C4: 1.5 | E4: Compton | F4: Jana | G4: FEB | H4: 10 | I4: Corvallis MOD 130 | J4: compton.jana@epa.gov | K4: 4620
A5: NBS 1577 Bovine Liver | B5: Bovine Liver | C5: 1 | E5: Dewitt | F5: Ted | G5: PCEB | H5: 19 | I5: Newport A-102 | J5: dewitt.ted@epa.gov | K5: 4029
A6: ISIRF Chitin | B6: Chitin | C6: 1 | E6: Faulkner | F6: Bart | G6: Ada | H6: 23
A7: NBS 1572 Citrus Leaf | B7: Citrus Leaf | C7: 2 | E7: Forshey | F7: Ken | G7: Ada | H7: 22
A8: NBS 8412 Corn Stalk | B8: Corn Stalk | C8: 6.5 | E8: Johnson | F8: Mark | G8: EEB | H8: 2 | I8: Corvallis PEB 112 | J8: johnson.markg@epa.gov | K8: 4696
A9: NBS 1575 Pine Needles | B9: Pine Needles | C9: 6.5 | E9: Kaldy | F9: Jim | G9: CEB | H9: 16 | I9: Newport A-124 | J9: kaldy.james@epa.gov | K9: 4026
A10: NIST 8541 Graphite | B10: Graphite | C10: 0.5 | E10: Lee | F10: Henry | G10: EEB | H10: 17 | I10: Corvallis PEB 117 | K10: 4832
A11: NIST 8542 Sucrose | B11: Sucrose | C11: 1 | E11: McKane | F11: Bob | G11: EEB | H11: 14 | I11: Corvallis SSB 202 | K11: 4631
A12: NIST 8550 Am Sulf | B12: Ammonium Sulfate | C12: 0.5 | E12: Nahlik | F12: Amanda | G12: FEB | H12: 24 | I12: Corvallis Main-208 | J12: nahlik.amanda@epa.gov | K12: 4581
A13: NIST 8551 Am Sulf | B13: Ammonium Sulfate | C13: 0.5 | E13: Olszyk | F13: Dave | G13: EEB | H13: 13 | I13: Corvallis SSB 206 | K13: 4397
A14: NIST 8573 Glutamic | B14: L-Glutamic | C14: 0.5 | E14: Rugh | F14: QA QC | G14: ISIRF | H14: 0 | I14: Corvallis Main-201 | J14: rugh.william@epa.gov | K14: 4604
A15: NIST 8574 Glutamic | B15: L-Glutamic | C15: 0.5 | E15: Trine | F15: QA QC | G15: ISIRF | H15: 0 | I15: Corvallis Main-201 | J15: Trine.Lisandra@epa.gov
A16: ISIRF Ulva | B16: Ulva | C16: 1.2 | E16: Weitzman | F16: Julie | G16: EEB/WQPB | H16: 25 | I16: Atlanta, GA (R4 Office) | J16: weitzman.julie@epa.gov
A17: USGS 42 Tib Hair | B17: Tibetan Hair | C17: 0.6
E18: Logical | H18: 13C
E19: Yes | H19: 15N
E20: No | H20: 13C15N
H21: 34S
E23: Todays Date | H23: Janice Chatfield
E24: =TODAY() -> 44057 | H24: Lisandra Trine
H25: William Rugh
H26: Other
E27: Text conversion to date
E28: =TEXT(E24,"yymmdd") -> 240815

Sheet Revisions
A1: Date | B1: Changes and comments | C1: initals
A2: 42542 | B2: New version. Drop down boxes added and look-up for SRM included. | C2: wdr
